Workbook

Sheet Base de datos
A1: CLIENTE | B1: PROYECTO | C1: RESPONSABLE | D1: CODIGO (PREDEFINIDO) | E1: COLABORADORES | F1: FECHA ENTREGA | G1: REFERENCIAS | H1: FOTO PIEZA | I1: UNIDADES | J1: NOMBRE PIEZA | AE1: CLIENTE | AF1: PROYECTO | AG1: RESPONSABLE | AH1: CODIGO (PREDEFINIDO) | AI1: COLABORADORES | AJ1: FECHA ENTREGA | AK1: REFERENCIAS | AL1: FOTO PIEZA | AM1: UNIDADES | AN1: NOMBRE PIEZA
A2: ='00-PROYECTO'!A2 -> Grupo palace | B2: ='00-PROYECTO'!B2 -> Beach palace | C2: ='00-PROYECTO'!C2 -> Mireia | D2: =IF(OR(A2="",B2="",C2=""),"",UPPER(LEFT(A2,1)&LEFT(B2,1)&"-"&LEFT(C2,1))) -> GB-M | E2: ='00-PROYECTO'!E2 -> LUIS | F2: ='00-PROYECTO'!F2 -> 46157 | G2: {=IF(INDEX('01-LISTADO_ELEMENTOS'!C:C,ROW()+5)<>"",LOOKUP(2,1/($D$2:D2<>""),$D$2:D2)&"-"&TEXT(COUNTIF('01-LISTADO_ELEMENTOS'!$C$7:INDEX('01-LISTADO_ELEMENTOS'!C:C,ROW()+5),"<>"),"000"),"")} -> GB-M-001 | H2: ='01-LISTADO_ELEMENTOS'!A7 | I2: ='01-LISTADO_ELEMENTOS'!D7 | J2: ='01-LISTADO_ELEMENTOS'!C7 -> Elefante | AE2: =IFERROR(__xludf.DUMMYFUNCTION("IMPORTRANGE(""1Uh1EKF3FsHh6pUypsVIS9FR5wAJZ_PHgLiHNgktyUps"",""Base de datos!A2:AD100"") "),"Grupo palace") -> Grupo palace | AF2: =IFERROR(__xludf.DUMMYFUNCTION("""COMPUTED_VALUE"""),"Beach palace") -> Beach palace | AG2: =IFERROR(__xludf.DUMMYFUNCTION("""COMPUTED_VALUE"""),"Mireia") -> Mireia | AH2: =IFERROR(__xludf.DUMMYFUNCTION("""COMPUTED_VALUE"""),"GB-M") -> GB-M | AI2: =IFERROR(__xludf.DUMMYFUNCTION("""COMPUTED_VALUE"""),"LUIS") -> LUIS | AJ2: =IFERROR(__xludf.DUMMYFUNCTION("""COMPUTED_VALUE"""),46157.0) -> 46157 | AK2: =IFERROR(__xludf.DUMMYFUNCTION("""COMPUTED_VALUE"""),"GB-M-001") -> GB-M-001 | AN2: =IFERROR(__xludf.DUMMYFUNCTION("""COMPUTED_VALUE"""),"Elefante") -> Elefante
E3: ='00-PROYECTO'!E3 -> PEDRO | G3: {=IF(INDEX('01-LISTADO_ELEMENTOS'!C:C,ROW()+5)<>"",LOOKUP(2,1/($D$2:D2<>""),$D$2:D3)&"-"&TEXT(COUNTIF('01-LISTADO_ELEMENTOS'!$C$7:INDEX('01-LISTADO_ELEMENTOS'!C:C,ROW()+5),"<>"),"000"),"")} | H3: ='01-LISTADO_ELEMENTOS'!A8 | I3: ='01-LISTADO_ELEMENTOS'!D8 | J3: ='01-LISTADO_ELEMENTOS'!C8 | AI3: =IFERROR(__xludf.DUMMYFUNCTION("""COMPUTED_VALUE"""),"PEDRO") -> PEDRO | AK3: =IFERROR(__xludf.DUMMYFUNCTION("""COMPUTED_VALUE"""),"")
E4: ='00-PROYECTO'!E4 -> JUAN | G4: {=IF(INDEX('01-LISTADO_ELEMENTOS'!C:C,ROW()+5)<>"",LOOKUP(2,1/($D$2:D2<>""),$D$2:D4)&"-"&TEXT(COUNTIF('01-LISTADO_ELEMENTOS'!$C$7:INDEX('01-LISTADO_ELEMENTOS'!C:C,ROW()+5),"<>"),"000"),"")} -> GB-M-002 | H4: ='01-LISTADO_ELEMENTOS'!A9 | I4: ='01-LISTADO_ELEMENTOS'!D9 | J4: ='01-LISTADO_ELEMENTOS'!C9 -> Cocodrilo | AI4: =IFERROR(__xludf.DUMMYFUNCTION("""COMPUTED_VALUE"""),"JUAN") -> JUAN | AK4: =IFERROR(__xludf.DUMMYFUNCTION("""COMPUTED_VALUE"""),"GB-M-002") -> GB-M-002 | AN4: =IFERROR(__xludf.DUMMYFUNCTION("""COMPUTED_VALUE"""),"Cocodrilo") -> Cocodrilo
E5: ='00-PROYECTO'!E5 -> ALBERTO | G5: {=IF(INDEX('01-LISTADO_ELEMENTOS'!C:C,ROW()+5)<>"",LOOKUP(2,1/($D$2:D2<>""),$D$2:D5)&"-"&TEXT(COUNTIF('01-LISTADO_ELEMENTOS'!$C$7:INDEX('01-LISTADO_ELEMENTOS'!C:C,ROW()+5),"<>"),"000"),"")} | H5: ='01-LISTADO_ELEMENTOS'!A10 | I5: ='01-LISTADO_ELEMENTOS'!D10 | J5: ='01-LISTADO_ELEMENTOS'!C10 | AI5: =IFERROR(__xludf.DUMMYFUNCTION("""COMPUTED_VALUE"""),"ALBERTO") -> ALBERTO | AK5: =IFERROR(__xludf.DUMMYFUNCTION("""COMPUTED_VALUE"""),"")
E6: ='00-PROYECTO'!E6 | G6: {=IF(INDEX('01-LISTADO_ELEMENTOS'!C:C,ROW()+5)<>"",LOOKUP(2,1/($D$2:D2<>""),$D$2:D5)&"-"&TEXT(COUNTIF('01-LISTADO_ELEMENTOS'!$C$7:INDEX('01-LISTADO_ELEMENTOS'!C:C,ROW()+5),"<>"),"000"),"")} | H6: ='01-LISTADO_ELEMENTOS'!A11 | I6: ='01-LISTADO_ELEMENTOS'!D11 | J6: ='01-LISTADO_ELEMENTOS'!C11 | AK6: =IFERROR(__xludf.DUMMYFUNCTION("""COMPUTED_VALUE"""),"")
E7: ='00-PROYECTO'!E7 | G7: {=IF(INDEX('01-LISTADO_ELEMENTOS'!C:C,ROW()+5)<>"",LOOKUP(2,1/($D$2:D2<>""),$D$2:D6)&"-"&TEXT(COUNTIF('01-LISTADO_ELEMENTOS'!$C$7:INDEX('01-LISTADO_ELEMENTOS'!C:C,ROW()+5),"<>"),"000"),"")} | H7: ='01-LISTADO_ELEMENTOS'!A12 | I7: ='01-LISTADO_ELEMENTOS'!D12 | J7: ='01-LISTADO_ELEMENTOS'!C12 | AK7: =IFERROR(__xludf.DUMMYFUNCTION("""COMPUTED_VALUE"""),"")
E8: ='00-PROYECTO'!E8 | G8: {=IF(INDEX('01-LISTADO_ELEMENTOS'!C:C,ROW()+5)<>"",LOOKUP(2,1/($D$2:D2<>""),$D$2:D5)&"-"&TEXT(COUNTIF('01-LISTADO_ELEMENTOS'!$C$7:INDEX('01-LISTADO_ELEMENTOS'!C:C,ROW()+5),"<>"),"000"),"")} | H8: ='01-LISTADO_ELEMENTOS'!A13 | I8: ='01-LISTADO_ELEMENTOS'!D13 | J8: ='01-LISTADO_ELEMENTOS'!C13 | AK8: =IFERROR(__xludf.DUMMYFUNCTION("""COMPUTED_VALUE"""),"")
E9: ='00-PROYECTO'!E9 | G9: {=IF(INDEX('01-LISTADO_ELEMENTOS'!C:C,ROW()+5)<>"",LOOKUP(2,1/($D$2:D2<>""),$D$2:D5)&"-"&TEXT(COUNTIF('01-LISTADO_ELEMENTOS'!$C$7:INDEX('01-LISTADO_ELEMENTOS'!C:C,ROW()+5),"<>"),"000"),"")} | H9: ='01-LISTADO_ELEMENTOS'!A14 | I9: ='01-LISTADO_ELEMENTOS'!D14 | J9: ='01-LISTADO_ELEMENTOS'!C14 | AK9: =IFERROR(__xludf.DUMMYFUNCTION("""COMPUTED_VALUE"""),"")
E10: ='00-PROYECTO'!E10 | G10: {=IF(INDEX('01-LISTADO_ELEMENTOS'!C:C,ROW()+5)<>"",LOOKUP(2,1/($D$2:D2<>""),$D$2:D5)&"-"&TEXT(COUNTIF('01-LISTADO_ELEMENTOS'!$C$7:INDEX('01-LISTADO_ELEMENTOS'!C:C,ROW()+5),"<>"),"000"),"")} | H10: ='01-LISTADO_ELEMENTOS'!A15 | I10: ='01-LISTADO_ELEMENTOS'!D15 | J10: ='01-LISTADO_ELEMENTOS'!C15 | AK10: =IFERROR(__xludf.DUMMYFUNCTION("""COMPUTED_VALUE"""),"")
E11: ='00-PROYECTO'!E11 | G11: {=IF(INDEX('01-LISTADO_ELEMENTOS'!C:C,ROW()+5)<>"",LOOKUP(2,1/($D$2:D2<>""),$D$2:D5)&"-"&TEXT(COUNTIF('01-LISTADO_ELEMENTOS'!$C$7:INDEX('01-LISTADO_ELEMENTOS'!C:C,ROW()+5),"<>"),"000"),"")} | H11: ='01-LISTADO_ELEMENTOS'!A16 | I11: ='01-LISTADO_ELEMENTOS'!D16 | J11: ='01-LISTADO_ELEMENTOS'!C16 | AK11: =IFERROR(__xludf.DUMMYFUNCTION("""COMPUTED_VALUE"""),"")
E12: ='00-PROYECTO'!E12 | G12: {=IF(INDEX('01-LISTADO_ELEMENTOS'!C:C,ROW()+5)<>"",LOOKUP(2,1/($D$2:D2<>""),$D$2:D5)&"-"&TEXT(COUNTIF('01-LISTADO_ELEMENTOS'!$C$7:INDEX('01-LISTADO_ELEMENTOS'!C:C,ROW()+5),"<>"),"000"),"")} | H12: ='01-LISTADO_ELEMENTOS'!A17 | I12: ='01-LISTADO_ELEMENTOS'!D17 | J12: ='01-LISTADO_ELEMENTOS'!C17 | AK12: =IFERROR(__xludf.DUMMYFUNCTION("""COMPUTED_VALUE"""),"")
E13: ='00-PROYECTO'!E13 | G13: {=IF(INDEX('01-LISTADO_ELEMENTOS'!C:C,ROW()+5)<>"",LOOKUP(2,1/($D$2:D2<>""),$D$2:D5)&"-"&TEXT(COUNTIF('01-LISTADO_ELEMENTOS'!$C$7:INDEX('01-LISTADO_ELEMENTOS'!C:C,ROW()+5),"<>"),"000"),"")} | H13: ='01-LISTADO_ELEMENTOS'!A18 | I13: ='01-LISTADO_ELEMENTOS'!D18 | J13: ='01-LISTADO_ELEMENTOS'!C18 | AK13: =IFERROR(__xludf.DUMMYFUNCTION("""COMPUTED_VALUE"""),"")
E14: ='00-PROYECTO'!E14 | G14: {=IF(INDEX('01-LISTADO_ELEMENTOS'!C:C,ROW()+5)<>"",LOOKUP(2,1/($D$2:D2<>""),$D$2:D6)&"-"&TEXT(COUNTIF('01-LISTADO_ELEMENTOS'!$C$7:INDEX('01-LISTADO_ELEMENTOS'!C:C,ROW()+5),"<>"),"000"),"")} | H14: ='01-LISTADO_ELEMENTOS'!A19 | I14: ='01-LISTADO_ELEMENTOS'!D19 | J14: ='01-LISTADO_ELEMENTOS'!C19 | AK14: =IFERROR(__xludf.DUMMYFUNCTION("""COMPUTED_VALUE"""),"")
E15: ='00-PROYECTO'!E15 | G15: {=IF(INDEX('01-LISTADO_ELEMENTOS'!C:C,ROW()+5)<>"",LOOKUP(2,1/($D$2:D2<>""),$D$2:D7)&"-"&TEXT(COUNTIF('01-LISTADO_ELEMENTOS'!$C$7:INDEX('01-LISTADO_ELEMENTOS'!C:C,ROW()+5),"<>"),"000"),"")} | H15: ='01-LISTADO_ELEMENTOS'!A20 | I15: ='01-LISTADO_ELEMENTOS'!D20 | J15: ='01-LISTADO_ELEMENTOS'!C20 | AK15: =IFERROR(__xludf.DUMMYFUNCTION("""COMPUTED_VALUE"""),"")
E16: ='00-PROYECTO'!E16 | G16: {=IF(INDEX('01-LISTADO_ELEMENTOS'!C:C,ROW()+5)<>"",LOOKUP(2,1/($D$2:D2<>""),$D$2:D8)&"-"&TEXT(COUNTIF('01-LISTADO_ELEMENTOS'!$C$7:INDEX('01-LISTADO_ELEMENTOS'!C:C,ROW()+5),"<>"),"000"),"")} | H16: ='01-LISTADO_ELEMENTOS'!A21 | I16: ='01-LISTADO_ELEMENTOS'!D21 | J16: ='01-LISTADO_ELEMENTOS'!C21 | AK16: =IFERROR(__xludf.DUMMYFUNCTION("""COMPUTED_VALUE"""),"")
E17: ='00-PROYECTO'!E17 | G17: {=IF(INDEX('01-LISTADO_ELEMENTOS'!C:C,ROW()+5)<>"",LOOKUP(2,1/($D$2:D2<>""),$D$2:D9)&"-"&TEXT(COUNTIF('01-LISTADO_ELEMENTOS'!$C$7:INDEX('01-LISTADO_ELEMENTOS'!C:C,ROW()+5),"<>"),"000"),"")} | H17: ='01-LISTADO_ELEMENTOS'!A22 | I17: ='01-LISTADO_ELEMENTOS'!D22 | J17: ='01-LISTADO_ELEMENTOS'!C22 | AK17: =IFERROR(__xludf.DUMMYFUNCTION("""COMPUTED_VALUE"""),"")
G18: {=IF(INDEX('01-LISTADO_ELEMENTOS'!C:C,ROW()+5)<>"",LOOKUP(2,1/($D$2:D2<>""),$D$2:D10)&"-"&TEXT(COUNTIF('01-LISTADO_ELEMENTOS'!$C$7:INDEX('01-LISTADO_ELEMENTOS'!C:C,ROW()+5),"<>"),"000"),"")} | H18: ='01-LISTADO_ELEMENTOS'!A23 | I18: ='01-LISTADO_ELEMENTOS'!D23 | J18: ='01-LISTADO_ELEMENTOS'!C23 | AK18: =IFERROR(__xludf.DUMMYFUNCTION("""COMPUTED_VALUE"""),"")
G19: {=IF(INDEX('01-LISTADO_ELEMENTOS'!C:C,ROW()+5)<>"",LOOKUP(2,1/($D$2:D2<>""),$D$2:D11)&"-"&TEXT(COUNTIF('01-LISTADO_ELEMENTOS'!$C$7:INDEX('01-LISTADO_ELEMENTOS'!C:C,ROW()+5),"<>"),"000"),"")} | H19: ='01-LISTADO_ELEMENTOS'!A24 | I19: ='01-LISTADO_ELEMENTOS'!D24 | J19: ='01-LISTADO_ELEMENTOS'!C24 | AK19: =IFERROR(__xludf.DUMMYFUNCTION("""COMPUTED_VALUE"""),"")
E20: ='00-PROYECTO'!E20 | G20: {=IF(INDEX('01-LISTADO_ELEMENTOS'!C:C,ROW()+5)<>"",LOOKUP(2,1/($D$2:D2<>""),$D$2:D11)&"-"&TEXT(COUNTIF('01-LISTADO_ELEMENTOS'!$C$7:INDEX('01-LISTADO_ELEMENTOS'!C:C,ROW()+5),"<>"),"000"),"")} | H20: ='01-LISTADO_ELEMENTOS'!A25 | I20: ='01-LISTADO_ELEMENTOS'!D25 | J20: ='01-LISTADO_ELEMENTOS'!C25 | AK20: =IFERROR(__xludf.DUMMYFUNCTION("""COMPUTED_VALUE"""),"")
E21: ='00-PROYECTO'!E21 | G21: {=IF(INDEX('01-LISTADO_ELEMENTOS'!C:C,ROW()+5)<>"",LOOKUP(2,1/($D$2:D2<>""),$D$2:D13)&"-"&TEXT(COUNTIF('01-LISTADO_ELEMENTOS'!$C$7:INDEX('01-LISTADO_ELEMENTOS'!C:C,ROW()+5),"<>"),"000"),"")} | H21: ='01-LISTADO_ELEMENTOS'!A26 | I21: ='01-LISTADO_ELEMENTOS'!D26 | J21: ='01-LISTADO_ELEMENTOS'!C26 | AK21: =IFERROR(__xludf.DUMMYFUNCTION("""COMPUTED_VALUE"""),"")
E22: ='00-PROYECTO'!E22 | G22: {=IF(INDEX('01-LISTADO_ELEMENTOS'!C:C,ROW()+5)<>"",LOOKUP(2,1/($D$2:D2<>""),$D$2:D14)&"-"&TEXT(COUNTIF('01-LISTADO_ELEMENTOS'!$C$7:INDEX('01-LISTADO_ELEMENTOS'!C:C,ROW()+5),"<>"),"000"),"")} | H22: ='01-LISTADO_ELEMENTOS'!A27 | I22: ='01-LISTADO_ELEMENTOS'!D27 | J22: ='01-LISTADO_ELEMENTOS'!C27 | AK22: =IFERROR(__xludf.DUMMYFUNCTION("""COMPUTED_VALUE"""),"")
E23: ='00-PROYECTO'!E23 | G23: {=IF(INDEX('01-LISTADO_ELEMENTOS'!C:C,ROW()+5)<>"",LOOKUP(2,1/($D$2:D2<>""),$D$2:D15)&"-"&TEXT(COUNTIF('01-LISTADO_ELEMENTOS'!$C$7:INDEX('01-LISTADO_ELEMENTOS'!C:C,ROW()+5),"<>"),"000"),"")} | H23: ='01-LISTADO_ELEMENTOS'!A28 | I23: ='01-LISTADO_ELEMENTOS'!D28 | J23: ='01-LISTADO_ELEMENTOS'!C28 | AK23: =IFERROR(__xludf.DUMMYFUNCTION("""COMPUTED_VALUE"""),"")
E24: ='00-PROYECTO'!E24 | G24: {=IF(INDEX('01-LISTADO_ELEMENTOS'!C:C,ROW()+5)<>"",LOOKUP(2,1/($D$2:D2<>""),$D$2:D16)&"-"&TEXT(COUNTIF('01-LISTADO_ELEMENTOS'!$C$7:INDEX('01-LISTADO_ELEMENTOS'!C:C,ROW()+5),"<>"),"000"),"")} | H24: ='01-LISTADO_ELEMENTOS'!A29 | I24: ='01-LISTADO_ELEMENTOS'!D29 | J24: ='01-LISTADO_ELEMENTOS'!C29 | AK24: =IFERROR(__xludf.DUMMYFUNCTION("""COMPUTED_VALUE"""),"")
E25: ='00-PROYECTO'!E25 | G25: {=IF(INDEX('01-LISTADO_ELEMENTOS'!C:C,ROW()+5)<>"",LOOKUP(2,1/($D$2:D2<>""),$D$2:D17)&"-"&TEXT(COUNTIF('01-LISTADO_ELEMENTOS'!$C$7:INDEX('01-LISTADO_ELEMENTOS'!C:C,ROW()+5),"<>"),"000"),"")} | H25: ='01-LISTADO_ELEMENTOS'!A30 | I25: ='01-LISTADO_ELEMENTOS'!D30 | J25: ='01-LISTADO_ELEMENTOS'!C30 | AK25: =IFERROR(__xludf.DUMMYFUNCTION("""COMPUTED_VALUE"""),"")
E26: ='00-PROYECTO'!E26 | G26: {=IF(INDEX('01-LISTADO_ELEMENTOS'!C:C,ROW()+5)<>"",LOOKUP(2,1/($D$2:D2<>""),$D$2:D18)&"-"&TEXT(COUNTIF('01-LISTADO_ELEMENTOS'!$C$7:INDEX('01-LISTADO_ELEMENTOS'!C:C,ROW()+5),"<>"),"000"),"")} | H26: ='01-LISTADO_ELEMENTOS'!A31 | I26: ='01-LISTADO_ELEMENTOS'!D31 | J26: ='01-LISTADO_ELEMENTOS'!C31 | AK26: =IFERROR(__xludf.DUMMYFUNCTION("""COMPUTED_VALUE"""),"")
E27: ='00-PROYECTO'!E18 | G27: {=IF(INDEX('01-LISTADO_ELEMENTOS'!C:C,ROW()+5)<>"",LOOKUP(2,1/($D$2:D2<>""),$D$2:D19)&"-"&TEXT(COUNTIF('01-LISTADO_ELEMENTOS'!$C$7:INDEX('01-LISTADO_ELEMENTOS'!C:C,ROW()+5),"<>"),"000"),"")} | H27: ='01-LISTADO_ELEMENTOS'!A32 | I27: ='01-LISTADO_ELEMENTOS'!D32 | J27: ='01-LISTADO_ELEMENTOS'!C32 | AK27: =IFERROR(__xludf.DUMMYFUNCTION("""COMPUTED_VALUE"""),"")
E28: ='00-PROYECTO'!E28 | G28: {=IF(INDEX('01-LISTADO_ELEMENTOS'!C:C,ROW()+5)<>"",LOOKUP(2,1/($D$2:D2<>""),$D$2:D20)&"-"&TEXT(COUNTIF('01-LISTADO_ELEMENTOS'!$C$7:INDEX('01-LISTADO_ELEMENTOS'!C:C,ROW()+5),"<>"),"000"),"")} | H28: ='01-LISTADO_ELEMENTOS'!A33 | I28: ='01-LISTADO_ELEMENTOS'!D33 | J28: ='01-LISTADO_ELEMENTOS'!C33 | AK28: =IFERROR(__xludf.DUMMYFUNCTION("""COMPUTED_VALUE"""),"")
E29: ='00-PROYECTO'!E29 | G29: {=IF(INDEX('01-LISTADO_ELEMENTOS'!C:C,ROW()+5)<>"",LOOKUP(2,1/($D$2:D2<>""),$D$2:D21)&"-"&TEXT(COUNTIF('01-LISTADO_ELEMENTOS'!$C$7:INDEX('01-LISTADO_ELEMENTOS'!C:C,ROW()+5),"<>"),"000"),"")} | H29: ='01-LISTADO_ELEMENTOS'!A34 | I29: ='01-LISTADO_ELEMENTOS'!D34 | J29: ='01-LISTADO_ELEMENTOS'!C34 | AK29: =IFERROR(__xludf.DUMMYFUNCTION("""COMPUTED_VALUE"""),"")
E30: ='00-PROYECTO'!E30 | G30: {=IF(INDEX('01-LISTADO_ELEMENTOS'!C:C,ROW()+5)<>"",LOOKUP(2,1/($D$2:D2<>""),$D$2:D22)&"-"&TEXT(COUNTIF('01-LISTADO_ELEMENTOS'!$C$7:INDEX('01-LISTADO_ELEMENTOS'!C:C,ROW()+5),"<>"),"000"),"")} | H30: ='01-LISTADO_ELEMENTOS'!A35 | I30: ='01-LISTADO_ELEMENTOS'!D35 | J30: ='01-LISTADO_ELEMENTOS'!C35 | AK30: =IFERROR(__xludf.DUMMYFUNCTION("""COMPUTED_VALUE"""),"")
E31: ='00-PROYECTO'!E31 | G31: {=IF(INDEX('01-LISTADO_ELEMENTOS'!C:C,ROW()+5)<>"",LOOKUP(2,1/($D$2:D2<>""),$D$2:D23)&"-"&TEXT(COUNTIF('01-LISTADO_ELEMENTOS'!$C$7:INDEX('01-LISTADO_ELEMENTOS'!C:C,ROW()+5),"<>"),"000"),"")} | H31: ='01-LISTADO_ELEMENTOS'!A36 | I31: ='01-LISTADO_ELEMENTOS'!D36 | J31: ='01-LISTADO_ELEMENTOS'!C36 | AK31: =IFERROR(__xludf.DUMMYFUNCTION("""COMPUTED_VALUE"""),"")
E32: ='00-PROYECTO'!E32 | G32: {=IF(INDEX('01-LISTADO_ELEMENTOS'!C:C,ROW()+5)<>"",LOOKUP(2,1/($D$2:D2<>""),$D$2:D24)&"-"&TEXT(COUNTIF('01-LISTADO_ELEMENTOS'!$C$7:INDEX('01-LISTADO_ELEMENTOS'!C:C,ROW()+5),"<>"),"000"),"")} | H32: ='01-LISTADO_ELEMENTOS'!A37 | I32: ='01-LISTADO_ELEMENTOS'!D37 | J32: ='01-LISTADO_ELEMENTOS'!C37 | AK32: =IFERROR(__xludf.DUMMYFUNCTION("""COMPUTED_VALUE"""),"")
E33: ='00-PROYECTO'!E33 | G33: {=IF(INDEX('01-LISTADO_ELEMENTOS'!C:C,ROW()+5)<>"",LOOKUP(2,1/($D$2:D2<>""),$D$2:D25)&"-"&TEXT(COUNTIF('01-LISTADO_ELEMENTOS'!$C$7:INDEX('01-LISTADO_ELEMENTOS'!C:C,ROW()+5),"<>"),"000"),"")} | H33: ='01-LISTADO_ELEMENTOS'!A38 | I33: ='01-LISTADO_ELEMENTOS'!D38 | J33: ='01-LISTADO_ELEMENTOS'!C38 | AK33: =IFERROR(__xludf.DUMMYFUNCTION("""COMPUTED_VALUE"""),"")
E34: ='00-PROYECTO'!E34 | G34: {=IF(INDEX('01-LISTADO_ELEMENTOS'!C:C,ROW()+5)<>"",LOOKUP(2,1/($D$2:D2<>""),$D$2:D26)&"-"&TEXT(COUNTIF('01-LISTADO_ELEMENTOS'!$C$7:INDEX('01-LISTADO_ELEMENTOS'!C:C,ROW()+5),"<>"),"000"),"")} | H34: ='01-LISTADO_ELEMENTOS'!A39 | I34: ='01-LISTADO_ELEMENTOS'!D39 | J34: ='01-LISTADO_ELEMENTOS'!C39 | AK34: =IFERROR(__xludf.DUMMYFUNCTION("""COMPUTED_VALUE"""),"")
E35: ='00-PROYECTO'!E35 | G35: {=IF(INDEX('01-LISTADO_ELEMENTOS'!C:C,ROW()+5)<>"",LOOKUP(2,1/($D$2:D2<>""),$D$2:D27)&"-"&TEXT(COUNTIF('01-LISTADO_ELEMENTOS'!$C$7:INDEX('01-LISTADO_ELEMENTOS'!C:C,ROW()+5),"<>"),"000"),"")} | H35: ='01-LISTADO_ELEMENTOS'!A40 | I35: ='01-LISTADO_ELEMENTOS'!D40 | J35: ='01-LISTADO_ELEMENTOS'!C40 | AK35: =IFERROR(__xludf.DUMMYFUNCTION("""COMPUTED_VALUE"""),"")
E36: ='00-PROYECTO'!E36 | G36: {=IF(INDEX('01-LISTADO_ELEMENTOS'!C:C,ROW()+5)<>"",LOOKUP(2,1/($D$2:D2<>""),$D$2:D28)&"-"&TEXT(COUNTIF('01-LISTADO_ELEMENTOS'!$C$7:INDEX('01-LISTADO_ELEMENTOS'!C:C,ROW()+5),"<>"),"000"),"")} | H36: ='01-LISTADO_ELEMENTOS'!A41 | I36: ='01-LISTADO_ELEMENTOS'!D41 | J36: ='01-LISTADO_ELEMENTOS'!C41 | AK36: =IFERROR(__xludf.DUMMYFUNCTION("""COMPUTED_VALUE"""),"")
E37: ='00-PROYECTO'!E37 | G37: {=IF(INDEX('01-LISTADO_ELEMENTOS'!C:C,ROW()+5)<>"",LOOKUP(2,1/($D$2:D2<>""),$D$2:D29)&"-"&TEXT(COUNTIF('01-LISTADO_ELEMENTOS'!$C$7:INDEX('01-LISTADO_ELEMENTOS'!C:C,ROW()+5),"<>"),"000"),"")} | H37: ='01-LISTADO_ELEMENTOS'!A42 | I37: ='01-LISTADO_ELEMENTOS'!D42 | J37: ='01-LISTADO_ELEMENTOS'!C42 | AK37: =IFERROR(__xludf.DUMMYFUNCTION("""COMPUTED_VALUE"""),"")
E38: ='00-PROYECTO'!E38 | G38: {=IF(INDEX('01-LISTADO_ELEMENTOS'!C:C,ROW()+5)<>"",LOOKUP(2,1/($D$2:D2<>""),$D$2:D30)&"-"&TEXT(COUNTIF('01-LISTADO_ELEMENTOS'!$C$7:INDEX('01-LISTADO_ELEMENTOS'!C:C,ROW()+5),"<>"),"000"),"")} | H38: ='01-LISTADO_ELEMENTOS'!A43 | I38: ='01-LISTADO_ELEMENTOS'!D43 | J38: ='01-LISTADO_ELEMENTOS'!C43 | AK38: =IFERROR(__xludf.DUMMYFUNCTION("""COMPUTED_VALUE"""),"")
E39: ='00-PROYECTO'!E39 | G39: {=IF(INDEX('01-LISTADO_ELEMENTOS'!C:C,ROW()+5)<>"",LOOKUP(2,1/($D$2:D2<>""),$D$2:D31)&"-"&TEXT(COUNTIF('01-LISTADO_ELEMENTOS'!$C$7:INDEX('01-LISTADO_ELEMENTOS'!C:C,ROW()+5),"<>"),"000"),"")} | H39: ='01-LISTADO_ELEMENTOS'!A44 | I39: ='01-LISTADO_ELEMENTOS'!D44 | J39: ='01-LISTADO_ELEMENTOS'!C44 | AK39: =IFERROR(__xludf.DUMMYFUNCTION("""COMPUTED_VALUE"""),"")
E40: ='00-PROYECTO'!E40 | G40: {=IF(INDEX('01-LISTADO_ELEMENTOS'!C:C,ROW()+5)<>"",LOOKUP(2,1/($D$2:D2<>""),$D$2:D32)&"-"&TEXT(COUNTIF('01-LISTADO_ELEMENTOS'!$C$7:INDEX('01-LISTADO_ELEMENTOS'!C:C,ROW()+5),"<>"),"000"),"")} | H40: ='01-LISTADO_ELEMENTOS'!A45 | I40: ='01-LISTADO_ELEMENTOS'!D45 | J40: ='01-LISTADO_ELEMENTOS'!C45 | AK40: =IFERROR(__xludf.DUMMYFUNCTION("""COMPUTED_VALUE"""),"")
...

Sheet HERRAMIENTAS
B2: CREAR PIEZAS EN PLANTILLA PRESUPUESTO | C2: TRUE

Sheet 00-PROYECTO
A1: NOMBRE CLIENTE | B1: PROYECTO | C1: RESPONSABLE | D1: CODIGO (PREDEFINIDO) | E1: COLABORADORES | F1: FECHA ENTREGA
A2: Grupo palace | B2: Beach palace | C2: Mireia | D2: ='Base de datos'!AH2 -> GB-M | E2: LUIS | F2: 46157
E3: PEDRO
E4: JUAN
A5: CREAR CARPETA PROYECTOS | B5: FALSE | E5: ALBERTO
A6: APROBADO EL PRESUPUESTO | B6: FALSE
A8: ¿Qué es
C23: COSTE FABRICACION
C24: PRECIO VENTA

Sheet 01-LISTADO_ELEMENTOS
A1: LINE-X HISPANIA, S.L. B-64084759 Carretera c-55 km 24. Raval dels Torrents. 08297-CASTELLGALI Telf: 938 789 622
A2: 0 | C2: ='Base de datos'!AE2 -> Grupo palace
A3: PROYECTO: | C3: ='Base de datos'!AF2 -> Beach palace
A4: FECHA ENTREGA: | C4: ='Base de datos'!AJ2 -> 46157
A6: FOTO | B6: REF | C6: Nombre | D6: UNIDADES | G6: ¿Cuanto gastamos de porex? | I6: ¿Cuanto ocupa en un container?
B7: ='Base de datos'!G2 -> GB-M-001 | C7: Elefante
B8: ='Base de datos'!G3
B9: ='Base de datos'!G4 -> GB-M-002 | C9: Cocodrilo
B10: ='Base de datos'!G5
B11: ='Base de datos'!G6
B12: ='Base de datos'!G7
B13: ='Base de datos'!G8
B14: ='Base de datos'!G9
B15: ='Base de datos'!G10
B16: ='Base de datos'!G11
B17: ='Base de datos'!G12
B18: ='Base de datos'!G13
B19: ='Base de datos'!G14
B20: ='Base de datos'!G15
B21: ='Base de datos'!G16
... B132: ='Base de datos'!G127

Sheet 02-LISTADO_MEDIDAS
A1: LINE-X HISPANIA, S.L. B-64084759 Carretera c-55 km 24. Raval dels Torrents. 08297-CASTELLGALI Telf: 938 789 622
A2: CLIENTE: | C2: ='Base de datos'!AE2 -> Grupo palace
A3: PROYECTO: | C3: ='Base de datos'!AF2 -> Beach palace
A4: FECHA: | C4: ='Base de datos'!AJ2 -> 46157
A6: FOTO Pieza | B6: REF | C6: Nombre | D6: UNIDADES | E6: MEDIDAS
A7: ='Base de datos'!AL2 | B7: ='Base de datos'!AK2 -> GB-M-001 | C7: ='Base de datos'!AN2 -> Elefante | D7: ='Base de datos'!AM2 | E7: 1000x1000x1000
A8: ='Base de datos'!AL3 | B8: ='Base de datos'!AK3 | C8: ='Base de datos'!AN3 | D8: ='Base de datos'!AM3
A9: ='Base de datos'!AL4 | B9: ='Base de datos'!AK4 -> GB-M-002 | D9: ='Base de datos'!AM4
A10: ='Base de datos'!AL5 | B10: ='Base de datos'!AK5 | C10: ='Base de datos'!AN5 | D10: ='Base de datos'!AM5
A11: ='Base de datos'!AL6 | B11: ='Base de datos'!AK6 | C11: ='Base de datos'!AN6 | D11: ='Base de datos'!AM6
A12: ='Base de datos'!AL7 | B12: ='Base de datos'!AK7 | C12: ='Base de datos'!AN7 | D12: ='Base de datos'!AM7
A13: ='Base de datos'!AL8 | B13: ='Base de datos'!AK8 | C13: ='Base de datos'!AN8 | D13: ='Base de datos'!AM8
A14: ='Base de datos'!AL9 | B14: ='Base de datos'!AK9 | C14: ='Base de datos'!AN9 | D14: ='Base de datos'!AM9
A15: ='Base de datos'!AL10 | B15: ='Base de datos'!AK10 | D15: ='Base de datos'!AM10
A16: ='Base de datos'!AL11 | B16: ='Base de datos'!AK11 | D16: ='Base de datos'!AM11
A17: ='Base de datos'!AL12 | B17: ='Base de datos'!AK12 | C17: ='Base de datos'!AN12 | D17: ='Base de datos'!AM12
A18: ='Base de datos'!AL13 | B18: ='Base de datos'!AK13 | C18: ='Base de datos'!AN13 | D18: ='Base de datos'!AM13
A19: ='Base de datos'!AL14 | B19: ='Base de datos'!AK14 | C19: ='Base de datos'!AN14 | D19: ='Base de datos'!AM14
A20: ='Base de datos'!AL15 | B20: ='Base de datos'!AK15 | C20: ='Base de datos'!AN15 | D20: ='Base de datos'!AM15
A21: ='Base de datos'!AL16 | B21: ='Base de datos'!AK16 | C21: ='Base de datos'!AN16 | D21: ='Base de datos'!AM16
A22: ='Base de datos'!AL17 | B22: ='Base de datos'!AK17 | C22: ='Base de datos'!AN17 | D22: ='Base de datos'!AM17
A23: ='Base de datos'!AL18 | B23: ='Base de datos'!AK18 | C23: ='Base de datos'!AN18 | D23: ='Base de datos'!AM18
A24: ='Base de datos'!AL19 | B24: ='Base de datos'!AK19 | C24: ='Base de datos'!AN19 | D24: ='Base de datos'!AM19
A25: ='Base de datos'!AL20 | B25: ='Base de datos'!AK20 | C25: ='Base de datos'!AN20 | D25: ='Base de datos'!AM20
A26: ='Base de datos'!AL21 | B26: ='Base de datos'!AK21 | C26: ='Base de datos'!AN21 | D26: ='Base de datos'!AM21
A27: ='Base de datos'!AL22 | B27: ='Base de datos'!AK22 | C27: ='Base de datos'!AN22 | D27: ='Base de datos'!AM22
A28: ='Base de datos'!AL23 | B28: ='Base de datos'!AK23 | C28: ='Base de datos'!AN23 | D28: ='Base de datos'!AM23
... A224: ='Base de datos'!AL219 | B224: ='Base de datos'!AK219 | C224: ='Base de datos'!AN219 | D224: ='Base de datos'!AM219
A225: ='Base de datos'!AL220 | B225: ='Base de datos'!AK220 | D225: ='Base de datos'!AM220
A226: ='Base de datos'!AL221 | B226: ='Base de datos'!AK221 | D226: ='Base de datos'!AM221
A227: ='Base de datos'!AL222 | B227: ='Base de datos'!AK222 | D227: ='Base de datos'!AM222
A228: ='Base de datos'!AL223 | B228: ='Base de datos'!AK223 | D228: ='Base de datos'!AM223
A229: ='Base de datos'!AL224 | B229: ='Base de datos'!AK224 | D229: ='Base de datos'!AM224
A230: ='Base de datos'!AL225 | B230: ='Base de datos'!AK225 | D230: ='Base de datos'!AM225
A231: ='Base de datos'!AL226 | B231: ='Base de datos'!AK226 | D231: ='Base de datos'!AM226
A232: ='Base de datos'!AL227 | B232: ='Base de datos'!AK227 | D232: ='Base de datos'!AM227
A233: ='Base de datos'!AL228 | B233: ='Base de datos'!AK228 | D233: ='Base de datos'!AM228
A234: ='Base de datos'!AL229 | B234: ='Base de datos'!AK229 | D234: ='Base de datos'!AM229
A235: ='Base de datos'!AL230 | B235: ='Base de datos'!AK230 | D235: ='Base de datos'!AM230
A236: ='Base de datos'!AL231 | B236: ='Base de datos'!AK231 | D236: ='Base de datos'!AM231
...

Sheet 03_CALCULO_PRESUPUESTO
B1: Proyecto: | M1: Cliente: | U1: Fecha: | X1: Porcentaje Linex: | AA1: 0.5
C2: m² | D2: m³ | F2: Uds | G2: Porex | H2: Line-X | I2: Fibra | J2: Pintura | K2: Mortero | L2: Oficina | M2: Program. | N2: Mecaniz. | O2: Pre-post | P2: Esculpir | Q2: Linex | R2: Fibra | S2: Mortero | T2: Pintura | U2: Estructura | V2: Entrega | W2: Otros | X2: HORAS | Y2: DÍAS | Z2: COSTE | AA2: PRECIO DE VENTA
B3: TOTAL | C3: =IFERROR(__xludf.DUMMYFUNCTION("IFERROR(SUMPRODUCT(FILTER(C5:C118*$F5:$F118,($A5:$A118=""Horas"")*(C5:C118)*($F5:$F118))),""0"") "),"0") -> 0 | D3: =IFERROR(__xludf.DUMMYFUNCTION("IFERROR(SUMPRODUCT(FILTER(D5:D118*$F5:$F118,($A5:$A118=""Horas"")*(D5:D118)*($F5:$F118))),""0"") "),"0") -> 0 | F3: =SUMIF($A:$A,"Horas",F:F) -> 0 | G3: según pieza | L3: =IFERROR(__xludf.DUMMYFUNCTION("IFERROR(SUMPRODUCT(FILTER(L5:L118,($A5:$A118=""Horas"")*(L5:L118)*($F5:$F118))),""0"") "),"0") -> 0 | M3: =IFERROR(__xludf.DUMMYFUNCTION("IFERROR(SUMPRODUCT(FILTER(M5:M118,($A5:$A118=""Horas"")*(M5:M118)*($F5:$F118))),""0"") "),"0") -> 0 | N3: =IFERROR(__xludf.DUMMYFUNCTION("IFERROR(SUMPRODUCT(FILTER(N5:N118*$F5:$F118,($A5:$A118=""Horas"")*(N5:N118)*($F5:$F118))),""0"") "),"0") -> 0 | O3: =IFERROR(__xludf.DUMMYFUNCTION("IFERROR(SUMPRODUCT(FILTER(O5:O118*$F5:$F118,($A5:$A118=""Horas"")*(O5:O118)*($F5:$F118))),""0"") "),"0") -> 0 | P3: =IFERROR(__xludf.DUMMYFUNCTION("IFERROR(SUMPRODUCT(FILTER(P5:P118*$F5:$F118,($A5:$A118=""Horas"")*(P5:P118)*($F5:$F118))),""0"") "),"0") -> 0 | Q3: =IFERROR(__xludf.DUMMYFUNCTION("IFERROR(SUMPRODUCT(FILTER(Q5:Q118*$F5:$F118,($A5:$A118=""Horas"")*(Q5:Q118)*($F5:$F118))),""0"") "),"0") -> 0 | R3: =IFERROR(__xludf.DUMMYFUNCTION("IFERROR(SUMPRODUCT(FILTER(R5:R118*$F5:$F118,($A5:$A118=""Horas"")*(R5:R118)*($F5:$F118))),""0"") "),"0") -> 0 | S3: =IFERROR(__xludf.DUMMYFUNCTION("IFERROR(SUMPRODUCT(FILTER(S5:S118*$F5:$F118,($A5:$A118=""Horas"")*(S5:S118)*($F5:$F118))),""0"") "),"0") -> 0 | T3: =IFERROR(__xludf.DUMMYFUNCTION("IFERROR(SUMPRODUCT(FILTER(T5:T118*$F5:$F118,($A5:$A118=""Horas"")*(T5:T118)*($F5:$F118))),""0"") "),"0") -> 0 | U3: =IFERROR(__xludf.DUMMYFUNCTION("IFERROR(SUMPRODUCT(FILTER(U5:U118*$F5:$F118,($A5:$A118=""Horas"")*(U5:U118)*($F5:$F118))),""0"") "),"0") -> 0 | V3: =IFERROR(__xludf.DUMMYFUNCTION("IFERROR(SUMPRODUCT(FILTER(V5:V118*$F5:$F118,($A5:$A118=""Horas"")*(V5:V118)*($F5:$F118))),""0"") "),"0") -> 0 | W3: =IFERROR(__xludf.DUMMYFUNCTION("IFERROR(SUMPRODUCT(FILTER(W5:W118*$F5:$F118,($A5:$A118=""Horas"")*(W5:W118)*($F5:$F118))),""0"") "),"0") -> 0 | X3: =SUM(L3:W3) -> 0 | Y3: =ROUNDUP((L3+MAX(M3,(N3/4),O3)+SUM(P3:W3))/8,0) -> 0 | Z3: =SUM(Z9:Z74) -> 0 | AA3: =SUM(AA9:AA74) -> 0
G4: =SUMIF($A:$A,"Coste",G:G) -> 0 | H4: =SUMIF($A:$A,"Coste",H:H) -> 0 | I4: =SUMIF($A:$A,"Coste",I:I) -> 0 | J4: =SUMIF($A:$A,"Coste",J:J) -> 0 | K4: =SUMIF($A:$A,"Coste",K:K) -> 0 | L4: =SUMIF($A:$A,"Coste",L:L) -> 0 | M4: =SUMIF($A:$A,"Coste",M:M) -> 0 | N4: =SUMIF($A:$A,"Coste",N:N) -> 0 | O4: =SUMIF($A:$A,"Coste",O:O) -> 0 | P4: =SUMIF($A:$A,"Coste",P:P) -> 0 | Q4: =SUMIF($A:$A,"Coste",Q:Q) -> 0 | R4: =SUMIF($A:$A,"Coste",R:R) -> 0 | S4: =SUMIF($A:$A,"Coste",S:S) -> 0 | T4: =SUMIF($A:$A,"Coste",T:T) -> 0 | U4: =SUMIF($A:$A,"Coste",U:U) -> 0 | V4: =SUMIF($A:$A,"Coste",V:V) -> 0 | W4: =SUMIF($A:$A,"Coste",W:W) -> 0
B6: PIEZA | G6: MATERIAL | L6: OFICINA | M6: ROBÓTICA (horas) | P6: TALLER (horas) | T6: PINTURA (horas) | U6: ESTRUCT | V6: ENTREGA | W6: OTROS | X6: TIEMPO PROD. | Z6: TOTAL
B7: Pieza y Medidas (mm) | C7: REF | D7: m² | E7: m³ | F7: Uds | G7: Porex (m³) | H7: Line-X (m²) | I7: Fibra (m²) | J7: Pintura (m²) | K7: Mortero (m²) | L7: OFs | M7: Programación | N7: Mecanizado | O7: Pegar/ lijar | P7: Esculpir | Q7: Line-X | R7: Fibra | S7: Mortero | T7: Pintura | U7: Estruct. | V7: Embalaje / carga | W7: Otros gastos | X7: HORAS | Y7: DÍAS | Z7: COSTE | AA7: + % | AB7: €/UD
B8: Costes: | G8: 90 | H8: 10 | I8: 12 | J8: 25 | K8: =380/2 -> 190 | L8: 25 | M8: 35 | N8: 15 | O8: 25 | P8: 25 | Q8: 25 | R8: 25 | S8: 25 | T8: 25 | U8: 25 | V8: 25
B9: Tornillo | C9: AB-M-001
B10: =#REF! -> #REF! | F10: 1 | G10: FALSE | K10: FALSE | M10: 8
B12: Tuerca | C12: AB-M-002
B13: =#REF! -> #REF!
B15: Arandela | C15: AB-M-003
B16: =#REF! -> #REF!
B18: Bisagra | C18: AB-M-004
B19: =#REF! -> #REF!
B21: Manilla | C21: AB-M-005
B22: =#REF! -> #REF!
B24: Cerradura | C24: AB-M-006
B25: =#REF! -> #REF!
B27: Cable | C27: AB-M-007
B28: =#REF! -> #REF!
B30: Interruptor | C30: AB-M-008
B31: =#REF! -> #REF!
B33: Enchufe | C33: AB-M-009
B34: =#REF! -> #REF!
B36: Bombilla | C36: AB-M-010
B37: =#REF! -> #REF!
B39: Martillo | C39: AB-M-011
B40: =#REF! -> #REF!
B42: Destornillador | C42: AB-M-012
B43: =#REF! -> #REF!
B45: Alicate | C45: AB-M-013
B46: =#REF! -> #REF!
B48: Llave inglesa | C48: AB-M-014
B49: =#REF! -> #REF!
B51: Taladro | C51: AB-M-015
B52: =#REF! -> #REF!
B54: Broca | C54: AB-M-016
B55: =#REF! -> #REF!
B57: Lija | C57: AB-M-017
...

Sheet Copia de 03_CALCULO_PRESUPUESTO
B1: Proyecto: | L1: Cliente: | T1: Fecha: | W1: Porcentaje Linex: | Z1: 0.5
C2: m² | D2: m³ | E2: Uds | F2: Porex | G2: Line-X | H2: Fibra | I2: Pintura | J2: Mortero | K2: Oficina | L2: Program. | M2: Mecaniz. | N2: Pre-post | O2: Esculpir | P2: Linex | Q2: Fibra | R2: Mortero | S2: Pintura | T2: Estructura | U2: Entrega | V2: Otros | W2: HORAS | X2: DÍAS | Y2: COSTE | Z2: PRECIO DE VENTA
B3: TOTAL | C3: =IFERROR(__xludf.DUMMYFUNCTION("IFERROR(SUMPRODUCT(FILTER(C5:C69*$E5:$E69,($A5:$A69=""Horas"")*(C5:C69)*($E5:$E69))),""0"") "),"0") -> 0 | D3: =IFERROR(__xludf.DUMMYFUNCTION("IFERROR(SUMPRODUCT(FILTER(D5:D69*$E5:$E69,($A5:$A69=""Horas"")*(D5:D69)*($E5:$E69))),""0"") "),"0") -> 0 | E3: =SUMIF($A:$A,"Horas",E:E) -> 1 | F3: según pieza | K3: =IFERROR(__xludf.DUMMYFUNCTION("IFERROR(SUMPRODUCT(FILTER(K5:K69,($A5:$A69=""Horas"")*(K5:K69)*($E5:$E69))),""0"") "),"0") -> 0 | L3: =IFERROR(__xludf.DUMMYFUNCTION("IFERROR(SUMPRODUCT(FILTER(L5:L69,($A5:$A69=""Horas"")*(L5:L69)*($E5:$E69))),""0"") "),8.0) -> 8 | M3: =IFERROR(__xludf.DUMMYFUNCTION("IFERROR(SUMPRODUCT(FILTER(M5:M69*$E5:$E69,($A5:$A69=""Horas"")*(M5:M69)*($E5:$E69))),""0"") "),48.0) -> 48 | N3: =IFERROR(__xludf.DUMMYFUNCTION("IFERROR(SUMPRODUCT(FILTER(N5:N69*$E5:$E69,($A5:$A69=""Horas"")*(N5:N69)*($E5:$E69))),""0"") "),"0") -> 0 | O3: =IFERROR(__xludf.DUMMYFUNCTION("IFERROR(SUMPRODUCT(FILTER(O5:O69*$E5:$E69,($A5:$A69=""Horas"")*(O5:O69)*($E5:$E69))),""0"") "),"0") -> 0 | P3: =IFERROR(__xludf.DUMMYFUNCTION("IFERROR(SUMPRODUCT(FILTER(P5:P69*$E5:$E69,($A5:$A69=""Horas"")*(P5:P69)*($E5:$E69))),""0"") "),"0") -> 0 | Q3: =IFERROR(__xludf.DUMMYFUNCTION("IFERROR(SUMPRODUCT(FILTER(Q5:Q69*$E5:$E69,($A5:$A69=""Horas"")*(Q5:Q69)*($E5:$E69))),""0"") "),"0") -> 0 | R3: =IFERROR(__xludf.DUMMYFUNCTION("IFERROR(SUMPRODUCT(FILTER(R5:R69*$E5:$E69,($A5:$A69=""Horas"")*(R5:R69)*($E5:$E69))),""0"") "),"0") -> 0 | S3: =IFERROR(__xludf.DUMMYFUNCTION("IFERROR(SUMPRODUCT(FILTER(S5:S69*$E5:$E69,($A5:$A69=""Horas"")*(S5:S69)*($E5:$E69))),""0"") "),"0") -> 0 | T3: =IFERROR(__xludf.DUMMYFUNCTION("IFERROR(SUMPRODUCT(FILTER(T5:T69*$E5:$E69,($A5:$A69=""Horas"")*(T5:T69)*($E5:$E69))),""0"") "),"0") -> 0 | U3: =IFERROR(__xludf.DUMMYFUNCTION("IFERROR(SUMPRODUCT(FILTER(U5:U69*$E5:$E69,($A5:$A69=""Horas"")*(U5:U69)*($E5:$E69))),""0"") "),"0") -> 0 | V3: =IFERROR(__xludf.DUMMYFUNCTION("IFERROR(SUMPRODUCT(FILTER(V5:V69*$E5:$E69,($A5:$A69=""Horas"")*(V5:V69)*($E5:$E69))),""0"") "),"0") -> 0 | W3: =SUM(K3:V3) -> 56 | X3: =ROUNDUP((K3+MAX(L3,(M3/4),N3)+SUM(O3:V3))/8,0) -> 2 | Y3: =SUM(Y9:Y25) -> 1000 | Z3: =SUM(Z9:Z25) -> 2000
F4: =SUMIF($A:$A,"Coste",F:F) -> 0 | G4: =SUMIF($A:$A,"Coste",G:G) -> 0 | H4: =SUMIF($A:$A,"Coste",H:H) -> 0 | I4: =SUMIF($A:$A,"Coste",I:I) -> 0 | J4: =SUMIF($A:$A,"Coste",J:J) -> 0 | K4: =SUMIF($A:$A,"Coste",K:K) -> 0 | L4: =SUMIF($A:$A,"Coste",L:L) -> 280 | M4: =SUMIF($A:$A,"Coste",M:M) -> 720 | N4: =SUMIF($A:$A,"Coste",N:N) -> 0 | O4: =SUMIF($A:$A,"Coste",O:O) -> 0 | P4: =SUMIF($A:$A,"Coste",P:P) -> 0 | Q4: =SUMIF($A:$A,"Coste",Q:Q) -> 0 | R4: =SUMIF($A:$A,"Coste",R:R) -> 0 | S4: =SUMIF($A:$A,"Coste",S:S) -> 0 | T4: =SUMIF($A:$A,"Coste",T:T) -> 0 | U4: =SUMIF($A:$A,"Coste",U:U) -> 0 | V4: =SUMIF($A:$A,"Coste",V:V) -> 0
B6: PIEZA | F6: MATERIAL | K6: OFICINA | L6: ROBÓTICA (horas) | O6: TALLER (horas) | S6: PINTURA (horas) | T6: ESTRUCT | U6: ENTREGA | V6: OTROS | W6: TIEMPO PROD. | Y6: TOTAL
B7: Pieza y Medidas (mm) | C7: m² | D7: m³ | E7: Uds | F7: Porex (m³) | G7: Line-X (m²) | H7: Fibra (m²) | I7: Pintura (m²) | J7: Mortero (m²) | K7: OFs | L7: Programación | M7: Mecanizado | N7: Pegar/ lijar | O7: Esculpir | P7: Line-X | Q7: Fibra | R7: Mortero | S7: Pintura | T7: Estruct. | U7: Embalaje / carga | V7: Otros gastos | W7: HORAS | X7: DÍAS | Y7: COSTE | Z7: + % | AA7: €/UD
B8: Costes: | F8: 90 | G8: 10 | H8: 12 | I8: 25 | J8: =380/2 -> 190 | K8: 25 | L8: 35 | M8: 15 | N8: 25 | O8: 25 | P8: 25 | Q8: 25 | R8: 25 | S8: 25 | T8: 25 | U8: 25
A9: =IF(E10,"Hay pieza","No hay pieza") -> Hay pieza | B9: NOMBRE_PIEZA | C9: m² | D9: m³ | E9: UNIDADES | F9: Porex | G9: Line-X | H9: Fibra | I9: Pintura | J9: Mortero | K9: OFs | L9: Program. | M9: Mecaniz. | N9: Pre-post | O9: Esculpir | P9: Linex | Q9: Fibra | R9: Mortero | S9: Pintura | T9: Estructura | U9: Entrega | V9: Otros | W9: HORAS | X9: DÍAS | Y9: COSTE | Z9: PVP | AA9: €/UD
A10: Horas | B10: FOTO PIEZA | E10: 1 | F10: FALSE | G10: FALSE | H10: FALSE | I10: FALSE | J10: FALSE | L10: 8 | M10: 48 | W10: =(K10+L10+SUM(M10:V10)*E10) -> 56 | X10: =ROUNDUP((K10+MAX(L10,(M10/4)*E10,N10*E10)+SUM(O10:V10)*E10)/8,0) -> 2 | Y10: =IF(E10>0,(K11+L11+SUM(F11:J11,M11:V11)),"No hay pieza") -> 1000 | Z10: =IF(E10>0,Y10/Z$1,"-") -> 2000 | AA10: =IF(E10>0,Z10/E10,"-") -> 2000
A11: Coste | F11: =IF(F10=TRUE,D10*F$8*E10,"- €") -> - € | G11: =IF(G10=TRUE,C10*G$8*E10,"- €") -> - € | H11: =IF(H10=TRUE,C10*H$8*E10,"- €") -> - € | I11: =IF(I10=TRUE,C10*I$8*E10,"- €") -> - € | J11: =IF(J10=TRUE,C10*J$8*E10,"- €") -> - € | K11: =IF($E10>0,K10*K$8,"- €") -> 0 | L11: =IF($E10>0,L10*L$8,"- €") -> 280 | M11: =IF($E10>0,M10*M$8*E10,"- €") -> 720 | N11: =IF($E10>0,N10*N$8*E10,"- €") -> 0 | O11: =IF($E10>0,O10*O$8*E10,"- €") -> 0 | P11: =IF(AND(G10=TRUE,$E10>0),P10*P$8*$E10,"- €") -> - € | Q11: =IF(AND(H10=TRUE,$E10>0),Q10*Q$8*$E10,"- €") -> - € | R11: =IF(AND(J10=TRUE,$E10>0),R10*R$8*$E10,"- €") -> - € | S11: =IF(AND(I10=TRUE,$E10>0),S10*S$8*$E10,"- €") -> - € | T11: =IF($E10>0,T10*T$8*E10,"- €") -> 0 | U11: =IF($E10>0,U10*U$8*E10,"- €") -> 0 | V11: =IF(Y$27>0,Y$27/E$3*E10,"- €") -> - €
A12: =IF(E13,"Hay pieza","No hay pieza") -> No hay pieza | B12: Pieza 2 | C12: m² | D12: m³ | E12: Uds | F12: Porex | G12: Line-X | H12: Fibra | I12: Pintura | J12: Mortero | K12: OFs | L12: Program. | M12: Mecaniz. | N12: Pre-post | O12: Esculpir | P12: Linex | Q12: Fibra | R12: Mortero | S12: Pintura | T12: Estructura | U12: Entrega | V12: Otros | W12: HORAS | X12: DÍAS | Y12: COSTE | Z12: PVP | AA12: €/UD
A13: Horas | F13: FALSE | G13: FALSE | H13: FALSE | I13: FALSE | J13: FALSE | W13: =(K13+L13+SUM(M13:V13)*E13) -> 0 | X13: =ROUNDUP((K13+MAX(L13,(M13/4)*E13,N13*E13)+SUM(O13:V13)*E13)/8,0) -> 0 | Y13: =IF(E13>0,(K14+L14+SUM(F14:J14,M14:V14)),"No hay pieza") -> No hay pieza | Z13: =IF(E13>0,Y13/Z$1,"-") -> - | AA13: =IF(E13>0,Z13/E13,"-") -> -
A14: Coste | F14: =IF(F13=TRUE,D13*F$8*E13,"- €") -> - € | G14: =IF(G13=TRUE,C13*G$8*E13,"- €") -> - € | H14: =IF(H13=TRUE,C13*H$8*E13,"- €") -> - € | I14: =IF(I13=TRUE,C13*I$8*E13,"- €") -> - € | J14: =IF(J13=TRUE,C13*J$8*E13,"- €") -> - € | K14: =IF($E13>0,K13*K$8,"- €") -> - € | L14: =IF($E13>0,L13*L$8,"- €") -> - € | M14: =IF($E13>0,M13*M$8*E13,"- €") -> - € | N14: =IF($E13>0,N13*N$8*E13,"- €") -> - € | O14: =IF($E13>0,O13*O$8*E13,"- €") -> - € | P14: =IF(AND(G13=TRUE,$E13>0),P13*P$8*$E13,"- €") -> - € | Q14: =IF(AND(H13=TRUE,$E13>0),Q13*Q$8*$E13,"- €") -> - € | R14: =IF(AND(J13=TRUE,$E13>0),R13*R$8*$E13,"- €") -> - € | S14: =IF(AND(I13=TRUE,$E13>0),S13*S$8*$E13,"- €") -> - € | T14: =IF($E13>0,T13*T$8*E13,"- €") -> - € | U14: =IF($E13>0,U13*U$8*E13,"- €") -> - € | V14: =IF(Y$27>0,Y$27/E$3*E13,"- €") -> - €
A15: =IF(E16,"Hay pieza","No hay pieza") -> No hay pieza | B15: Pieza 3 | C15: m² | D15: m³ | E15: Uds | F15: Porex | G15: Line-X | H15: Fibra | I15: Pintura | J15: Mortero | K15: OFs | L15: Program. | M15: Mecaniz. | N15: Pre-post | O15: Esculpir | P15: Linex | Q15: Fibra | R15: Mortero | S15: Pintura | T15: Estructura | U15: Entrega | V15: Otros | W15: HORAS | X15: DÍAS | Y15: COSTE | Z15: PVP | AA15: €/UD
A16: Horas | F16: FALSE | G16: FALSE | H16: FALSE | I16: FALSE | J16: FALSE | W16: =(K16+L16+SUM(M16:V16)*E16) -> 0 | X16: =ROUNDUP((K16+MAX(L16,(M16/4)*E16,N16*E16)+SUM(O16:V16)*E16)/8,0) -> 0 | Y16: =IF(E16>0,(K17+L17+SUM(F17:J17,M17:V17)),"No hay pieza") -> No hay pieza | Z16: =IF(E16>0,Y16/Z$1,"-") -> - | AA16: =IF(E16>0,Z16/E16,"-") -> -
A17: Coste | F17: =IF(F16=TRUE,D16*F$8*E16,"- €") -> - € | G17: =IF(G16=TRUE,C16*G$8*E16,"- €") -> - € | H17: =IF(H16=TRUE,C16*H$8*E16,"- €") -> - € | I17: =IF(I16=TRUE,C16*I$8*E16,"- €") -> - € | J17: =IF(J16=TRUE,C16*J$8*E16,"- €") -> - € | K17: =IF($E16>0,K16*K$8,"- €") -> - € | L17: =IF($E16>0,L16*L$8,"- €") -> - € | M17: =IF($E16>0,M16*M$8*E16,"- €") -> - € | N17: =IF($E16>0,N16*N$8*E16,"- €") -> - € | O17: =IF($E16>0,O16*O$8*E16,"- €") -> - € | P17: =IF(AND(G16=TRUE,$E16>0),P16*P$8*$E16,"- €") -> - € | Q17: =IF(AND(H16=TRUE,$E16>0),Q16*Q$8*$E16,"- €") -> - € | R17: =IF(AND(J16=TRUE,$E16>0),R16*R$8*$E16,"- €") -> - € | S17: =IF(AND(I16=TRUE,$E16>0),S16*S$8*$E16,"- €") -> - € | T17: =IF($E16>0,T16*T$8*E16,"- €") -> - € | U17: =IF($E16>0,U16*U$8*E16,"- €") -> - € | V17: =IF(Y$27>0,Y$27/E$3*E16,"- €") -> - €
B20: TRANSPORTE | C20: ¿Requiere? | F20: Distancia (km) | H20: Coche | J20: Furgo Iveco | L20: Ferry | N20: Contenedor 20ft | P20: Contenedor 40ft | R20: Camión | T20: Gasolina | V20: TRANSPORTISTA | Y20: TOTAL
D21: FALSE | T21: =IF(AND(D21=TRUE,OR(NOT(ISBLANK(H21)),NOT(ISBLANK(J21)))), F21*0.15*(H21+J21), "") | Y21: =IF(D21=TRUE,SUM(H22:W22),"Sin transporte") -> Sin transporte | Z21: =IF(D21=TRUE,Y21/Z$1,"-") -> -
H22: =IF($D21=TRUE,0.2*$F21*H21*2,"- €") -> - € | J22: =IF($D21=TRUE,0.4*$F21*J21*2,"- €") -> - € | L22: =IF($D21=TRUE,500*L21*2,"- €") -> - € | N22: =IF($D21=TRUE,3000*N21,"- €") -> - € | P22: =IF($D21=TRUE,6000*P21,"- €") -> - € | R22: =IF($D21=TRUE,1.7*$F21*R21,"- €") -> - € | T22: =T21*1.5 -> 0 | V22: =V21
B23: INSTALACIÓN | D23: ¿Requiere? | F23: Personas | H23: Días | J23: € Desplaz/pers | L23: € Noche/pers | N23: Mano de obra | P23: Viajes | R23: Alojamientos | T23: Comidas | V23: Gasolina | X23: HORAS | Y23: TOTAL
D24: FALSE | N24: =F24*H24*25*8 -> 0 | P24: =F24*J24*2 -> 0 | R24: =F24*(H24-1)*L24 -> 0 | T24: =F24*H24*35 -> 0 | X24: =F24*H24*8 -> 0 | Y24: =IF(D24=TRUE,SUM(N24:W24),"Sin instalación") -> Sin instalación | Z24: =IF(D24=TRUE,Y24/Z$1,"-") -> -
B26: OTROS GASTOS | F26: Gasto 1 | H26: Gasto 2 | J26: Gasto 3 | L26: Gasto 4 | N26: Gasto 5 | P26: Gasto 6 | R26: Gasto 7 | T26: Gasto 8 | V26: Gasto 9 | Y26: TOTAL
C27: Materiales y subcontratas | Y27: =SUM(F27:W27) -> 0 | Z27: =IF(Y27,Y27,"-") -> -

Sheet 04_01_PRESUPUESTO
A1: LINE-X HISPANIA, S.L. B-64084759 Carretera c-55 km 24. Raval dels Torrents. 08297-CASTELLGALI Telf: 938 789 622
A2: CLIENTE: | B2: ='Base de datos'!AE2 -> Grupo palace | C2: =IFERROR(#REF!,"")
A3: PROYECTO: | B3: ='Base de datos'!AF2 -> Beach palace | C3: =IFERROR(#REF!,"")
A4: FECHA: | B4: ='Base de datos'!AJ2 -> 46157 | C4: =IFERROR(#REF!,"")
A6: FOTO PIEZA | B6: REF | C6: Concepto | D6: Medidas | E6: UDS | F6: Precio SPOT | G6: Precio unidad | H6: Total
B7: =IFERROR(#REF!,"") | C7: =IFERROR(#REF!,"") | E7: =IFERROR(#REF!,"") | G7: =IFERROR(#REF!,"") | H7: =IF(E7*G7=0,"",E7*G7)
B8: =IFERROR(#REF!,"") | C8: =IFERROR(#REF!,"") | E8: =IFERROR(#REF!,"") | G8: =IFERROR(#REF!,"") | H8: =IF(E8*G8=0,"",E8*G8)
B9: =IFERROR(#REF!,"") | C9: =IFERROR(#REF!,"") | E9: =IFERROR(#REF!,"") | G9: =IFERROR(#REF!,"") | H9: =IF(E9*G9=0,"",E9*G9)
B10: =IFERROR(#REF!,"") | C10: =IFERROR(#REF!,"") | E10: =IFERROR(#REF!,"") | G10: =IFERROR(#REF!,"") | H10: =IF(E10*G10=0,"",E10*G10)
B11: =IFERROR(#REF!,"") | C11: =IFERROR(#REF!,"") | E11: =IFERROR(#REF!,"") | G11: =IFERROR(#REF!,"") | H11: =IF(E11*G11=0,"",E11*G11)
B12: =IFERROR(#REF!,"") | C12: =IFERROR(#REF!,"") | E12: =IFERROR(#REF!,"") | G12: =IFERROR(#REF!,"") | H12: =IF(E12*G12=0,"",E12*G12)
B13: =IFERROR(#REF!,"") | C13: =IFERROR(#REF!,"") | E13: =IFERROR(#REF!,"") | G13: =IFERROR(#REF!,"") | H13: =IF(E13*G13=0,"",E13*G13)
B14: =IFERROR(#REF!,"") | C14: =IFERROR(#REF!,"") | E14: =IFERROR(#REF!,"") | G14: =IFERROR(#REF!,"") | H14: =IF(E14*G14=0,"",E14*G14)
B15: =IFERROR(#REF!,"") | C15: =IFERROR(#REF!,"") | E15: =IFERROR(#REF!,"") | G15: =IFERROR(#REF!,"") | H15: =IF(E15*G15=0,"",E15*G15)
B16: =IFERROR(#REF!,"") | C16: =IFERROR(#REF!,"") | E16: =IFERROR(#REF!,"") | G16: =IFERROR(#REF!,"") | H16: =IF(E16*G16=0,"",E16*G16)
B17: =IFERROR(#REF!,"") | C17: =IFERROR(#REF!,"") | E17: =IFERROR(#REF!,"") | G17: =IFERROR(#REF!,"") | H17: =IF(E17*G17=0,"",E17*G17)
B18: =IFERROR(#REF!,"") | C18: =IFERROR(#REF!,"") | E18: =IFERROR(#REF!,"") | G18: =IFERROR(#REF!,"") | H18: =IF(E18*G18=0,"",E18*G18)
... B40: =IFERROR(#REF!,"") | C40: =IFERROR(#REF!,"") | E40: =IFERROR(#REF!,"") | G40: =IFERROR(#REF!,"") | H40: =IF(E40*G40=0,"",E40*G40)
B41: =IFERROR(#REF!,"") | C41: =IFERROR(#REF!,"") | E41: =IFERROR(#REF!,"") | G41: =IFERROR(#REF!,"") | H41: =IF(E41*G41=0,"",E41*G41) | I41: Confirmar medidas. Render?
B42: =IFERROR(#REF!,"") | C42: =IFERROR(#REF!,"") | E42: =IFERROR(#REF!,"") | G42: =IFERROR(#REF!,"") | H42: =IF(E42*G42=0,"",E42*G42) | I42: Passar Xina per pressu (Rachel y Aimee)
B43: =IFERROR(#REF!,"") | C43: =IFERROR(#REF!,"") | E43: =IFERROR(#REF!,"") | G43: =IFERROR(#REF!,"") | H43: =IF(E43*G43=0,"",E43*G43) | I43: Passar Xina per pressu (Rachel y Aimee)
B44: =IFERROR(#REF!,"") | C44: =IFERROR(#REF!,"") | E44: =IFERROR(#REF!,"") | G44: =IFERROR(#REF!,"") | H44: =IF(E44*G44=0,"",E44*G44)
B45: =IFERROR(#REF!,"") | C45: =IFERROR(#REF!,"") | E45: =IFERROR(#REF!,"") | G45: =IFERROR(#REF!,"") | H45: =IF(E45*G45=0,"",E45*G45) | I45: Passar Xina per pressu (Rachel y Aimee)
B46: =IFERROR(#REF!,"") | C46: =IFERROR(#REF!,"") | E46: =IFERROR(#REF!,"") | G46: =IFERROR(#REF!,"") | H46: =IF(E46*G46=0,"",E46*G46) | I46: Passar Xina per pressu (Rachel y Aimee)
B47: =IFERROR(#REF!,"") | C47: =IFERROR(#REF!,"") | E47: =IFERROR(#REF!,"") | G47: =IFERROR(#REF!,"") | H47: =IF(E47*G47=0,"",E47*G47) | I47: Passar Xina per pressu (Rachel y Aimee)
B48: =IFERROR(#REF!,"") | C48: =IFERROR(#REF!,"") | E48: =IFERROR(#REF!,"") | G48: =IFERROR(#REF!,"") | H48: =IF(E48*G48=0,"",E48*G48) | I48: Passar Xina per pressu (Rachel y Aimee)
B49: =IFERROR(#REF!,"") | C49: =IFERROR(#REF!,"") | E49: =IFERROR(#REF!,"") | G49: =IFERROR(#REF!,"") | H49: =IF(E49*G49=0,"",E49*G49) | I49: Passar Xina per pressu (Rachel y Aimee)
B50: =IFERROR(#REF!,"") | C50: =IFERROR(#REF!,"") | E50: =IFERROR(#REF!,"") | G50: =IFERROR(#REF!,"") | H50: =IF(E50*G50=0,"",E50*G50) | I50: Passar Xina per pressu (Rachel y Aimee)
B51: =IFERROR(#REF!,"") | C51: =IFERROR(#REF!,"") | E51: =IFERROR(#REF!,"") | G51: =IFERROR(#REF!,"") | H51: =IF(E51*G51=0,"",E51*G51) | I51: Passar Xina per pressu (Rachel y Aimee)
B52: =IFERROR(#REF!,"") | C52: =IFERROR(#REF!,"") | E52: =IFERROR(#REF!,"") | G52: =IFERROR(#REF!,"") | H52: =IF(E52*G52=0,"",E52*G52) | I52: Passar Xina per pressu (Rachel y Aimee)
B53: =IFERROR(#REF!,"") | C53: =IFERROR(#REF!,"") | E53: =IFERROR(#REF!,"") | G53: =IFERROR(#REF!,"") | H53: =IF(E53*G53=0,"",E53*G53)
B54: =IFERROR(#REF!,"") | C54: =IFERROR(#REF!,"") | E54: =IFERROR(#REF!,"") | G54: =IFERROR(#REF!,"") | H54: =IF(E54*G54=0,"",E54*G54)
B55: =IFERROR(#REF!,"") | C55: =IFERROR(#REF!,"") | E55: =IFERROR(#REF!,"") | G55: =IFERROR(#REF!,"") | H55: =IF(E55*G55=0,"",E55*G55)
B56: =IFERROR(#REF!,"") | C56: =IFERROR(#REF!,"") | E56: =IFERROR(#REF!,"") | G56: =IFERROR(#REF!,"") | H56: =IF(E56*G56=0,"",E56*G56)
C57: =IFERROR(#REF!,"") | E57: =IFERROR(#REF!,"") | G57: =IFERROR(#REF!,"") | H57: =IF(E57*G57=0,"",E57*G57)
G58: SUBTOTAL SUMINISTROS | H58: =SUM(H7:H57) -> 0
C60: Presupuesto provisional hasta tener toda la información y documentación del proyecto
A62: Por LINE-X HISPANIA, S.L. | E62: Por CLIENTE
A63: Administrador
A66: Julio Macias
...

Sheet 04_PRESUPUESTO
A1: LINE-X HISPANIA, S.L. B-64084759 Carretera c-55 km 24. Raval dels Torrents. 08297-CASTELLGALI Telf: 938 789 622
A2: CLIENTE: | B2: =IFERROR(#REF!,"")
A6: PROYECTOS: | B6: =IFERROR(#REF!,"")
A9: FECHA: | B9: =IFERROR(#REF!,"")
B12: Concepto | C12: Uds | D12: Precio unidad | E12: Total
B14: Pieza 1 | E14: =IF(C14,C14*D14,"")
E15: =IF(C15,C15*D15,"")
E16: =IF(C16,C16*D16,"")
E17: =IF(C17,C17*D17,"")
E18: =IF(C18,C18*D18,"")
E19: =IF(C19,C19*D19,"")
E20: =IF(C20,C20*D20,"")
E21: =IF(C21,C21*D21,"")
E22: =IF(C22,C22*D22,"")
E23: =IF(C23,C23*D23,"")
E24: =IF(C24,C24*D24,"")
B25: Las muestras solicitadas por el cliente tendrán un coste adicional
B27: Entrega de las piezas EXW
E28: =IF(C28,C28*D28,"")
D30: Subtotal | E30: =SUM(E14:E29) -> 0
D31: + IVA 21% | E31: =E30*0.21 -> 0
D32: TOTAL .............. | E32: =E30+E31 -> 0
A35: Por LINE-X HISPANIA, S.L. | C35: Por CLIENTE
A36: Administrador
A41: Julio Macias
A43: NO INCLUIDO: | B43: diseño personalizado, transporte de los elementos, montaje o instalación
A44: FORMA PAGO: | B44: 50% a la firma del presupuesto y el resto del 50% antes de la entrega
A45: IBAN | B45: ES17 2100 0440 1802 0016 8996
A46: IMPORTANTE: | B46: Cualquier cambio por parte del cliente en el proceso de producción, implicará un nuevo cambio en la fecha de entrega y del presupuesto.
B47: La fabricación se iniciará a partir de recibir el primer pago.
B48: Cualquier impuesto local, será a cargo del cliente.
B49: Para ejecutar la obra se necesitará la zona libre de personas y vehículos.
B50: A partir de la jornada de 8 horas, se consideran horas extras
B51: A partir de las 10:00 PM hasta las 6:00 AM, se consideran horas nocturnas
B52: Las horas extras se facturaran aparte.
B53: Al finalizar la obra se efectuarán nuevas mediciones
A55: En nombre de la empresa LINE-X HISPANIA, S. L., tratamos la información que nos facilita con el fin de poder hacer efectivo nuestro servicio/cumplir con nuestra relación comercial, y realizar la facturación del mismo. Los datos proporcionados se conservarán mientras se mantenga la relación comercial o durante los años necesarios para cumplir con las obligaciones legales. Los datos no se cederán a terceros salvo en los casos en que exista una obligación legal. Usted tiene derecho a obtener confirmación sobre si en LINE-X HISPANIA, S. L. estamos tratando sus datos personales por tanto tiene derecho a acceder a sus datos personales, rectificar los datos inexactos o solicitar su supresión cuando los datos ya no sean necesarios.

Sheet Horas obra
B1: ='03-CALCULO_COSTES'!D1 -> #REF!
B2: Total horas | C2: Trabajador 1 | H2: Trabajador 2 | M2: Trabajador 3 | R2: Trabajador 4 | W2: Trabajador 5 | AB2: Trabajador 6 | AG2: Trabajador 7 | AL2: Trabajador 8 | AQ2: Trabajador 9 | AV2: Trabajador 10 | BA2: Trabajador 11 | BF2: Trabajador 12 | BK2: Trabajador 13 | BP2: Trabajador 14 | BU2: Trabajador 15 | BZ2: Trabajador 16
B3: =SUM(C3:CD3) -> 0 | C3: =SUM(C4:C43) -> 0 | D3: Entrada | E3: Salida | F3: Entrada | G3: Salida | H3: =SUM(H4:H43) -> 0 | I3: Entrada | J3: Salida | K3: Entrada | L3: Salida | M3: =SUM(M4:M43) -> 0 | N3: Entrada | O3: Salida | P3: Entrada | Q3: Salida | R3: =SUM(R4:R43) -> 0 | S3: Entrada | T3: Salida | U3: Entrada | V3: Salida | W3: =SUM(W4:W43) -> 0 | X3: Entrada | Y3: Salida | Z3: Entrada | AA3: Salida | AB3: =SUM(AB4:AB43) -> 0 | AC3: Entrada | AD3: Salida | AE3: Entrada | AF3: Salida | AG3: =SUM(AG4:AG43) -> 0 | AH3: Entrada | AI3: Salida | AJ3: Entrada | AK3: Salida | AL3: =SUM(AL4:AL43) -> 0 | AM3: Entrada | AN3: Salida | AO3: Entrada | AP3: Salida | AQ3: =SUM(AQ4:AQ43) -> 0 | AR3: Entrada | AS3: Salida | AT3: Entrada | AU3: Salida | AV3: =SUM(AV4:AV43) -> 0 | AW3: Entrada | AX3: Salida | AY3: Entrada | AZ3: Salida | BA3: =SUM(BA4:BA43) -> 0 | BB3: Entrada | BC3: Salida | BD3: Entrada | BE3: Salida | BF3: =SUM(BF4:BF43) -> 0 | BG3: Entrada | BH3: Salida | BI3: Entrada | BJ3: Salida | BK3: =SUM(BK4:BK43) -> 0 | BL3: Entrada | BM3: Salida | BN3: Entrada | BO3: Salida | BP3: =SUM(BP4:BP43) -> 0 | BQ3: Entrada | BR3: Salida | BS3: Entrada | BT3: Salida | BU3: =SUM(BU4:BU43) -> 0 | BV3: Entrada | BW3: Salida | BX3: Entrada | BY3: Salida | BZ3: =SUM(BZ4:BZ43) -> 0 | CA3: Entrada | CB3: Salida | CC3: Entrada | CD3: Salida
C4: =IF(D4,E4-D4+G4-F4,"") | H4: =IF(I4,J4-I4+L4-K4,"") | M4: =IF(N4,O4-N4+Q4-P4,"") | R4: =IF(S4,T4-S4+V4-U4,"") | W4: =IF(X4,Y4-X4+AA4-Z4,"") | AB4: =IF(AC4,AD4-AC4+AF4-AE4,"") | AG4: =IF(AH4,AI4-AH4+AK4-AJ4,"") | AL4: =IF(AM4,AN4-AM4+AP4-AO4,"") | AQ4: =IF(AR4,AS4-AR4+AU4-AT4,"") | AV4: =IF(AW4,AX4-AW4+AZ4-AY4,"") | BA4: =IF(BB4,BC4-BB4+BE4-BD4,"") | BF4: =IF(BG4,BH4-BG4+BJ4-BI4,"") | BK4: =IF(BL4,BM4-BL4+BO4-BN4,"") | BP4: =IF(BQ4,BR4-BQ4+BT4-BS4,"") | BU4: =IF(BV4,BW4-BV4+BY4-BX4,"") | BZ4: =IF(CA4,CB4-CA4+CD4-CC4,"")
C5: =IF(D5,E5-D5+G5-F5,"") | H5: =IF(I5,J5-I5+L5-K5,"") | M5: =IF(N5,O5-N5+Q5-P5,"") | R5: =IF(S5,T5-S5+V5-U5,"") | W5: =IF(X5,Y5-X5+AA5-Z5,"") | AB5: =IF(AC5,AD5-AC5+AF5-AE5,"") | AG5: =IF(AH5,AI5-AH5+AK5-AJ5,"") | AL5: =IF(AM5,AN5-AM5+AP5-AO5,"") | AQ5: =IF(AR5,AS5-AR5+AU5-AT5,"") | AV5: =IF(AW5,AX5-AW5+AZ5-AY5,"") | BA5: =IF(BB5,BC5-BB5+BE5-BD5,"") | BF5: =IF(BG5,BH5-BG5+BJ5-BI5,"") | BK5: =IF(BL5,BM5-BL5+BO5-BN5,"") | BP5: =IF(BQ5,BR5-BQ5+BT5-BS5,"") | BU5: =IF(BV5,BW5-BV5+BY5-BX5,"") | BZ5: =IF(CA5,CB5-CA5+CD5-CC5,"")
C6: =IF(D6,E6-D6+G6-F6,"") | H6: =IF(I6,J6-I6+L6-K6,"") | M6: =IF(N6,O6-N6+Q6-P6,"") | R6: =IF(S6,T6-S6+V6-U6,"") | W6: =IF(X6,Y6-X6+AA6-Z6,"") | AB6: =IF(AC6,AD6-AC6+AF6-AE6,"") | AG6: =IF(AH6,AI6-AH6+AK6-AJ6,"") | AL6: =IF(AM6,AN6-AM6+AP6-AO6,"") | AQ6: =IF(AR6,AS6-AR6+AU6-AT6,"") | AV6: =IF(AW6,AX6-AW6+AZ6-AY6,"") | BA6: =IF(BB6,BC6-BB6+BE6-BD6,"") | BF6: =IF(BG6,BH6-BG6+BJ6-BI6,"") | BK6: =IF(BL6,BM6-BL6+BO6-BN6,"") | BP6: =IF(BQ6,BR6-BQ6+BT6-BS6,"") | BU6: =IF(BV6,BW6-BV6+BY6-BX6,"") | BZ6: =IF(CA6,CB6-CA6+CD6-CC6,"")
C7: =IF(D7,E7-D7+G7-F7,"") | AB7: =IF(AC7,AD7-AC7+AF7-AE7,"") | AG7: =IF(AH7,AI7-AH7+AK7-AJ7,"") | AL7: =IF(AM7,AN7-AM7+AP7-AO7,"") | AQ7: =IF(AR7,AS7-AR7+AU7-AT7,"") | AV7: =IF(AW7,AX7-AW7+AZ7-AY7,"") | BA7: =IF(BB7,BC7-BB7+BE7-BD7,"") | BF7: =IF(BG7,BH7-BG7+BJ7-BI7,"") | BK7: =IF(BL7,BM7-BL7+BO7-BN7,"") | BP7: =IF(BQ7,BR7-BQ7+BT7-BS7,"") | BU7: =IF(BV7,BW7-BV7+BY7-BX7,"") | BZ7: =IF(CA7,CB7-CA7+CD7-CC7,"")
C8: =IF(D8,E8-D8+G8-F8,"") | AB8: =IF(AC8,AD8-AC8+AF8-AE8,"") | AG8: =IF(AH8,AI8-AH8+AK8-AJ8,"") | AL8: =IF(AM8,AN8-AM8+AP8-AO8,"") | AQ8: =IF(AR8,AS8-AR8+AU8-AT8,"") | AV8: =IF(AW8,AX8-AW8+AZ8-AY8,"") | BA8: =IF(BB8,BC8-BB8+BE8-BD8,"") | BF8: =IF(BG8,BH8-BG8+BJ8-BI8,"") | BK8: =IF(BL8,BM8-BL8+BO8-BN8,"") | BP8: =IF(BQ8,BR8-BQ8+BT8-BS8,"") | BU8: =IF(BV8,BW8-BV8+BY8-BX8,"") | BZ8: =IF(CA8,CB8-CA8+CD8-CC8,"")
C9: =IF(D9,E9-D9+G9-F9,"") | AB9: =IF(AC9,AD9-AC9+AF9-AE9,"") | AG9: =IF(AH9,AI9-AH9+AK9-AJ9,"") | AL9: =IF(AM9,AN9-AM9+AP9-AO9,"") | AQ9: =IF(AR9,AS9-AR9+AU9-AT9,"") | AV9: =IF(AW9,AX9-AW9+AZ9-AY9,"") | BA9: =IF(BB9,BC9-BB9+BE9-BD9,"") | BF9: =IF(BG9,BH9-BG9+BJ9-BI9,"") | BK9: =IF(BL9,BM9-BL9+BO9-BN9,"") | BP9: =IF(BQ9,BR9-BQ9+BT9-BS9,"") | BU9: =IF(BV9,BW9-BV9+BY9-BX9,"") | BZ9: =IF(CA9,CB9-CA9+CD9-CC9,"")
C10: =IF(D10,E10-D10+G10-F10,"") | AB10: =IF(AC10,AD10-AC10+AF10-AE10,"") | AG10: =IF(AH10,AI10-AH10+AK10-AJ10,"") | AL10: =IF(AM10,AN10-AM10+AP10-AO10,"") | AQ10: =IF(AR10,AS10-AR10+AU10-AT10,"") | AV10: =IF(AW10,AX10-AW10+AZ10-AY10,"") | BA10: =IF(BB10,BC10-BB10+BE10-BD10,"") | BF10: =IF(BG10,BH10-BG10+BJ10-BI10,"") | BK10: =IF(BL10,BM10-BL10+BO10-BN10,"") | BP10: =IF(BQ10,BR10-BQ10+BT10-BS10,"") | BU10: =IF(BV10,BW10-BV10+BY10-BX10,"") | BZ10: =IF(CA10,CB10-CA10+CD10-CC10,"")
C11: =IF(D11,E11-D11+G11-F11,"") | AB11: =IF(AC11,AD11-AC11+AF11-AE11,"") | AG11: =IF(AH11,AI11-AH11+AK11-AJ11,"") | AL11: =IF(AM11,AN11-AM11+AP11-AO11,"") | AQ11: =IF(AR11,AS11-AR11+AU11-AT11,"") | AV11: =IF(AW11,AX11-AW11+AZ11-AY11,"") | BA11: =IF(BB11,BC11-BB11+BE11-BD11,"") | BF11: =IF(BG11,BH11-BG11+BJ11-BI11,"") | BK11: =IF(BL11,BM11-BL11+BO11-BN11,"") | BP11: =IF(BQ11,BR11-BQ11+BT11-BS11,"") | BU11: =IF(BV11,BW11-BV11+BY11-BX11,"") | BZ11: =IF(CA11,CB11-CA11+CD11-CC11,"")
C12: =IF(D12,E12-D12+G12-F12,"") | AB12: =IF(AC12,AD12-AC12+AF12-AE12,"") | AG12: =IF(AH12,AI12-AH12+AK12-AJ12,"") | AL12: =IF(AM12,AN12-AM12+AP12-AO12,"") | AQ12: =IF(AR12,AS12-AR12+AU12-AT12,"") | AV12: =IF(AW12,AX12-AW12+AZ12-AY12,"") | BA12: =IF(BB12,BC12-BB12+BE12-BD12,"") | BF12: =IF(BG12,BH12-BG12+BJ12-BI12,"") | BK12: =IF(BL12,BM12-BL12+BO12-BN12,"") | BP12: =IF(BQ12,BR12-BQ12+BT12-BS12,"") | BU12: =IF(BV12,BW12-BV12+BY12-BX12,"") | BZ12: =IF(CA12,CB12-CA12+CD12-CC12,"")
C13: =IF(D13,E13-D13+G13-F13,"") | AB13: =IF(AC13,AD13-AC13+AF13-AE13,"") | AG13: =IF(AH13,AI13-AH13+AK13-AJ13,"") | AL13: =IF(AM13,AN13-AM13+AP13-AO13,"") | AQ13: =IF(AR13,AS13-AR13+AU13-AT13,"") | AV13: =IF(AW13,AX13-AW13+AZ13-AY13,"") | BA13: =IF(BB13,BC13-BB13+BE13-BD13,"") | BF13: =IF(BG13,BH13-BG13+BJ13-BI13,"") | BK13: =IF(BL13,BM13-BL13+BO13-BN13,"") | BP13: =IF(BQ13,BR13-BQ13+BT13-BS13,"") | BU13: =IF(BV13,BW13-BV13+BY13-BX13,"") | BZ13: =IF(CA13,CB13-CA13+CD13-CC13,"")
C14: =IF(D14,E14-D14+G14-F14,"") | AB14: =IF(AC14,AD14-AC14+AF14-AE14,"") | AG14: =IF(AH14,AI14-AH14+AK14-AJ14,"") | AL14: =IF(AM14,AN14-AM14+AP14-AO14,"") | AQ14: =IF(AR14,AS14-AR14+AU14-AT14,"") | AV14: =IF(AW14,AX14-AW14+AZ14-AY14,"") | BA14: =IF(BB14,BC14-BB14+BE14-BD14,"") | BF14: =IF(BG14,BH14-BG14+BJ14-BI14,"") | BK14: =IF(BL14,BM14-BL14+BO14-BN14,"") | BP14: =IF(BQ14,BR14-BQ14+BT14-BS14,"") | BU14: =IF(BV14,BW14-BV14+BY14-BX14,"") | BZ14: =IF(CA14,CB14-CA14+CD14-CC14,"")
C15: =IF(D15,E15-D15+G15-F15,"") | AB15: =IF(AC15,AD15-AC15+AF15-AE15,"") | AG15: =IF(AH15,AI15-AH15+AK15-AJ15,"") | AL15: =IF(AM15,AN15-AM15+AP15-AO15,"") | AQ15: =IF(AR15,AS15-AR15+AU15-AT15,"") | AV15: =IF(AW15,AX15-AW15+AZ15-AY15,"") | BA15: =IF(BB15,BC15-BB15+BE15-BD15,"") | BF15: =IF(BG15,BH15-BG15+BJ15-BI15,"") | BK15: =IF(BL15,BM15-BL15+BO15-BN15,"") | BP15: =IF(BQ15,BR15-BQ15+BT15-BS15,"") | BU15: =IF(BV15,BW15-BV15+BY15-BX15,"") | BZ15: =IF(CA15,CB15-CA15+CD15-CC15,"")
C16: =IF(D16,E16-D16+G16-F16,"") | AB16: =IF(AC16,AD16-AC16+AF16-AE16,"") | AG16: =IF(AH16,AI16-AH16+AK16-AJ16,"") | AL16: =IF(AM16,AN16-AM16+AP16-AO16,"") | AQ16: =IF(AR16,AS16-AR16+AU16-AT16,"") | AV16: =IF(AW16,AX16-AW16+AZ16-AY16,"") | BA16: =IF(BB16,BC16-BB16+BE16-BD16,"") | BF16: =IF(BG16,BH16-BG16+BJ16-BI16,"") | BK16: =IF(BL16,BM16-BL16+BO16-BN16,"") | BP16: =IF(BQ16,BR16-BQ16+BT16-BS16,"") | BU16: =IF(BV16,BW16-BV16+BY16-BX16,"") | BZ16: =IF(CA16,CB16-CA16+CD16-CC16,"")
C17: =IF(D17,E17-D17+G17-F17,"") | AB17: =IF(AC17,AD17-AC17+AF17-AE17,"") | AG17: =IF(AH17,AI17-AH17+AK17-AJ17,"") | AL17: =IF(AM17,AN17-AM17+AP17-AO17,"") | AQ17: =IF(AR17,AS17-AR17+AU17-AT17,"") | AV17: =IF(AW17,AX17-AW17+AZ17-AY17,"") | BA17: =IF(BB17,BC17-BB17+BE17-BD17,"") | BF17: =IF(BG17,BH17-BG17+BJ17-BI17,"") | BK17: =IF(BL17,BM17-BL17+BO17-BN17,"") | BP17: =IF(BQ17,BR17-BQ17+BT17-BS17,"") | BU17: =IF(BV17,BW17-BV17+BY17-BX17,"") | BZ17: =IF(CA17,CB17-CA17+CD17-CC17,"")
C18: =IF(D18,E18-D18+G18-F18,"") | AB18: =IF(AC18,AD18-AC18+AF18-AE18,"") | AG18: =IF(AH18,AI18-AH18+AK18-AJ18,"") | AL18: =IF(AM18,AN18-AM18+AP18-AO18,"") | AQ18: =IF(AR18,AS18-AR18+AU18-AT18,"") | AV18: =IF(AW18,AX18-AW18+AZ18-AY18,"") | BA18: =IF(BB18,BC18-BB18+BE18-BD18,"") | BF18: =IF(BG18,BH18-BG18+BJ18-BI18,"") | BK18: =IF(BL18,BM18-BL18+BO18-BN18,"") | BP18: =IF(BQ18,BR18-BQ18+BT18-BS18,"") | BU18: =IF(BV18,BW18-BV18+BY18-BX18,"") | BZ18: =IF(CA18,CB18-CA18+CD18-CC18,"")
... C24: =IF(D24,E24-D24+G24-F24,"") | AB24: =IF(AC24,AD24-AC24+AF24-AE24,"") | AG24: =IF(AH24,AI24-AH24+AK24-AJ24,"") | AL24: =IF(AM24,AN24-AM24+AP24-AO24,"") | AQ24: =IF(AR24,AS24-AR24+AU24-AT24,"") | AV24: =IF(AW24,AX24-AW24+AZ24-AY24,"") | BA24: =IF(BB24,BC24-BB24+BE24-BD24,"") | BF24: =IF(BG24,BH24-BG24+BJ24-BI24,"") | BK24: =IF(BL24,BM24-BL24+BO24-BN24,"") | BP24: =IF(BQ24,BR24-BQ24+BT24-BS24,"") | BU24: =IF(BV24,BW24-BV24+BY24-BX24,"") | BZ24: =IF(CA24,CB24-CA24+CD24-CC24,"")
C25: =IF(D25,E25-D25+G25-F25,"") | H25: =IF(I25,J25-I25+L25-K25,"") | M25: =IF(N25,O25-N25+Q25-P25,"") | R25: =IF(S25,T25-S25+V25-U25,"") | W25: =IF(X25,Y25-X25+AA25-Z25,"") | AB25: =IF(AC25,AD25-AC25+AF25-AE25,"") | AG25: =IF(AH25,AI25-AH25+AK25-AJ25,"") | AL25: =IF(AM25,AN25-AM25+AP25-AO25,"") | AQ25: =IF(AR25,AS25-AR25+AU25-AT25,"") | AV25: =IF(AW25,AX25-AW25+AZ25-AY25,"") | BA25: =IF(BB25,BC25-BB25+BE25-BD25,"") | BF25: =IF(BG25,BH25-BG25+BJ25-BI25,"") | BK25: =IF(BL25,BM25-BL25+BO25-BN25,"") | BP25: =IF(BQ25,BR25-BQ25+BT25-BS25,"") | BU25: =IF(BV25,BW25-BV25+BY25-BX25,"") | BZ25: =IF(CA25,CB25-CA25+CD25-CC25,"")
C26: =IF(D26,E26-D26+G26-F26,"") | H26: =IF(I26,J26-I26+L26-K26,"") | M26: =IF(N26,O26-N26+Q26-P26,"") | R26: =IF(S26,T26-S26+V26-U26,"") | W26: =IF(X26,Y26-X26+AA26-Z26,"") | AB26: =IF(AC26,AD26-AC26+AF26-AE26,"") | AG26: =IF(AH26,AI26-AH26+AK26-AJ26,"") | AL26: =IF(AM26,AN26-AM26+AP26-AO26,"") | AQ26: =IF(AR26,AS26-AR26+AU26-AT26,"") | AV26: =IF(AW26,AX26-AW26+AZ26-AY26,"") | BA26: =IF(BB26,BC26-BB26+BE26-BD26,"") | BF26: =IF(BG26,BH26-BG26+BJ26-BI26,"") | BK26: =IF(BL26,BM26-BL26+BO26-BN26,"") | BP26: =IF(BQ26,BR26-BQ26+BT26-BS26,"") | BU26: =IF(BV26,BW26-BV26+BY26-BX26,"") | BZ26: =IF(CA26,CB26-CA26+CD26-CC26,"")
C27: =IF(D27,E27-D27+G27-F27,"") | H27: =IF(I27,J27-I27+L27-K27,"") | M27: =IF(N27,O27-N27+Q27-P27,"") | R27: =IF(S27,T27-S27+V27-U27,"") | W27: =IF(X27,Y27-X27+AA27-Z27,"") | AB27: =IF(AC27,AD27-AC27+AF27-AE27,"") | AG27: =IF(AH27,AI27-AH27+AK27-AJ27,"") | AL27: =IF(AM27,AN27-AM27+AP27-AO27,"") | AQ27: =IF(AR27,AS27-AR27+AU27-AT27,"") | AV27: =IF(AW27,AX27-AW27+AZ27-AY27,"") | BA27: =IF(BB27,BC27-BB27+BE27-BD27,"") | BF27: =IF(BG27,BH27-BG27+BJ27-BI27,"") | BK27: =IF(BL27,BM27-BL27+BO27-BN27,"") | BP27: =IF(BQ27,BR27-BQ27+BT27-BS27,"") | BU27: =IF(BV27,BW27-BV27+BY27-BX27,"") | BZ27: =IF(CA27,CB27-CA27+CD27-CC27,"")
C28: =IF(D28,E28-D28+G28-F28,"") | H28: =IF(I28,J28-I28+L28-K28,"") | M28: =IF(N28,O28-N28+Q28-P28,"") | R28: =IF(S28,T28-S28+V28-U28,"") | W28: =IF(X28,Y28-X28+AA28-Z28,"") | AB28: =IF(AC28,AD28-AC28+AF28-AE28,"") | AG28: =IF(AH28,AI28-AH28+AK28-AJ28,"") | AL28: =IF(AM28,AN28-AM28+AP28-AO28,"") | AQ28: =IF(AR28,AS28-AR28+AU28-AT28,"") | AV28: =IF(AW28,AX28-AW28+AZ28-AY28,"") | BA28: =IF(BB28,BC28-BB28+BE28-BD28,"") | BF28: =IF(BG28,BH28-BG28+BJ28-BI28,"") | BK28: =IF(BL28,BM28-BL28+BO28-BN28,"") | BP28: =IF(BQ28,BR28-BQ28+BT28-BS28,"") | BU28: =IF(BV28,BW28-BV28+BY28-BX28,"") | BZ28: =IF(CA28,CB28-CA28+CD28-CC28,"")
C29: =IF(D29,E29-D29+G29-F29,"") | H29: =IF(I29,J29-I29+L29-K29,"") | M29: =IF(N29,O29-N29+Q29-P29,"") | R29: =IF(S29,T29-S29+V29-U29,"") | W29: =IF(X29,Y29-X29+AA29-Z29,"") | AB29: =IF(AC29,AD29-AC29+AF29-AE29,"") | AG29: =IF(AH29,AI29-AH29+AK29-AJ29,"") | AL29: =IF(AM29,AN29-AM29+AP29-AO29,"") | AQ29: =IF(AR29,AS29-AR29+AU29-AT29,"") | AV29: =IF(AW29,AX29-AW29+AZ29-AY29,"") | BA29: =IF(BB29,BC29-BB29+BE29-BD29,"") | BF29: =IF(BG29,BH29-BG29+BJ29-BI29,"") | BK29: =IF(BL29,BM29-BL29+BO29-BN29,"") | BP29: =IF(BQ29,BR29-BQ29+BT29-BS29,"") | BU29: =IF(BV29,BW29-BV29+BY29-BX29,"") | BZ29: =IF(CA29,CB29-CA29+CD29-CC29,"")
C30: =IF(D30,E30-D30+G30-F30,"") | H30: =IF(I30,J30-I30+L30-K30,"") | M30: =IF(N30,O30-N30+Q30-P30,"") | R30: =IF(S30,T30-S30+V30-U30,"") | W30: =IF(X30,Y30-X30+AA30-Z30,"") | AB30: =IF(AC30,AD30-AC30+AF30-AE30,"") | AG30: =IF(AH30,AI30-AH30+AK30-AJ30,"") | AL30: =IF(AM30,AN30-AM30+AP30-AO30,"") | AQ30: =IF(AR30,AS30-AR30+AU30-AT30,"") | AV30: =IF(AW30,AX30-AW30+AZ30-AY30,"") | BA30: =IF(BB30,BC30-BB30+BE30-BD30,"") | BF30: =IF(BG30,BH30-BG30+BJ30-BI30,"") | BK30: =IF(BL30,BM30-BL30+BO30-BN30,"") | BP30: =IF(BQ30,BR30-BQ30+BT30-BS30,"") | BU30: =IF(BV30,BW30-BV30+BY30-BX30,"") | BZ30: =IF(CA30,CB30-CA30+CD30-CC30,"")
C31: =IF(D31,E31-D31+G31-F31,"") | H31: =IF(I31,J31-I31+L31-K31,"") | M31: =IF(N31,O31-N31+Q31-P31,"") | R31: =IF(S31,T31-S31+V31-U31,"") | W31: =IF(X31,Y31-X31+AA31-Z31,"") | AB31: =IF(AC31,AD31-AC31+AF31-AE31,"") | AG31: =IF(AH31,AI31-AH31+AK31-AJ31,"") | AL31: =IF(AM31,AN31-AM31+AP31-AO31,"") | AQ31: =IF(AR31,AS31-AR31+AU31-AT31,"") | AV31: =IF(AW31,AX31-AW31+AZ31-AY31,"") | BA31: =IF(BB31,BC31-BB31+BE31-BD31,"") | BF31: =IF(BG31,BH31-BG31+BJ31-BI31,"") | BK31: =IF(BL31,BM31-BL31+BO31-BN31,"") | BP31: =IF(BQ31,BR31-BQ31+BT31-BS31,"") | BU31: =IF(BV31,BW31-BV31+BY31-BX31,"") | BZ31: =IF(CA31,CB31-CA31+CD31-CC31,"")
C32: =IF(D32,E32-D32+G32-F32,"") | H32: =IF(I32,J32-I32+L32-K32,"") | M32: =IF(N32,O32-N32+Q32-P32,"") | R32: =IF(S32,T32-S32+V32-U32,"") | W32: =IF(X32,Y32-X32+AA32-Z32,"") | AB32: =IF(AC32,AD32-AC32+AF32-AE32,"") | AG32: =IF(AH32,AI32-AH32+AK32-AJ32,"") | AL32: =IF(AM32,AN32-AM32+AP32-AO32,"") | AQ32: =IF(AR32,AS32-AR32+AU32-AT32,"") | AV32: =IF(AW32,AX32-AW32+AZ32-AY32,"") | BA32: =IF(BB32,BC32-BB32+BE32-BD32,"") | BF32: =IF(BG32,BH32-BG32+BJ32-BI32,"") | BK32: =IF(BL32,BM32-BL32+BO32-BN32,"") | BP32: =IF(BQ32,BR32-BQ32+BT32-BS32,"") | BU32: =IF(BV32,BW32-BV32+BY32-BX32,"") | BZ32: =IF(CA32,CB32-CA32+CD32-CC32,"")
